Workbook

Sheet INGENIERIA
B2: CODIGO PT | C2: CODIGO MP | D2: DESCRIPCION | E2: UM | F2: CONSUMO | G2: COSTO | H2: TOTAL MP
B3: 9001 | C3: PRODUCTO A | J3: A) | K3: LISTA DE MATERIALES DE CADA PRODUCTO
C4: 1001 | D4: MATERIA PRIMA A | E4: KGS | F4: 1 | G4: =VLOOKUP(C4,COMPRAS!B:E,4,0) -> 100 | H4: =F4*G4 -> 100 | J4: B) | K4: TIEMPOS DE PROCESO DE CADA PRODUCTO
C5: 1002 | D5: MATERIA PRIMA B | E5: KGS | F5: 0.5 | G5: =VLOOKUP(C5,COMPRAS!B:E,4,0) -> 55 | H5: =F5*G5 -> 27.5 | J5: C) | K5: RUTA DE PRODUCCION DE CADA PRODUCTO
C6: 1003 | D6: MATERIA PRIMA C | E6: KGS | F6: 0.32 | G6: =VLOOKUP(C6,COMPRAS!B:E,4,0) -> 20 | H6: =F6*G6 -> 6.4
C7: 1004 | D7: MATERIA PRIMA D | E7: KGS | F7: 2 | G7: =VLOOKUP(C7,COMPRAS!B:E,4,0) -> 34 | H7: =F7*G7 -> 68
C8: 1005 | D8: MATERIA PRIMA E | E8: KGS | F8: 0.67 | G8: =VLOOKUP(C8,COMPRAS!B:E,4,0) -> 15 | H8: =F8*G8 -> 10.05
C9: 1006 | D9: MATERIA PRIMA F | E9: KGS | F9: 0.2 | G9: =VLOOKUP(C9,COMPRAS!B:E,4,0) -> 67 | H9: =F9*G9 -> 13.4
C10: 1007 | D10: MATERIA PRIMA G | E10: KGS | F10: 0.1 | G10: =VLOOKUP(C10,COMPRAS!B:E,4,0) -> 22 | H10: =F10*G10 -> 2.2
C11: 1008 | D11: MATERIA PRIMA H | E11: KGS | F11: 0.8 | G11: =VLOOKUP(C11,COMPRAS!B:E,4,0) -> 35 | H11: =F11*G11 -> 28
C12: 1009 | D12: MATERIA PRIMA I | E12: PZA | F12: 1 | G12: =VLOOKUP(C12,COMPRAS!B:E,4,0) -> 15 | H12: =F12*G12 -> 15
C13: 1010 | D13: MATERIA PRIMA J | E13: PZA | F13: 1 | G13: =VLOOKUP(C13,COMPRAS!B:E,4,0) -> 10 | H13: =F13*G13 -> 10
C14: WC1 1P | D14: TIEMPO DE PROCESO 1 | E14: MIN | F14: 5
C15: WC1 2P | D15: TIEMPO DE PROCESO 2 | E15: MIN | F15: 7
C16: WC1 3P | D16: TIEMPO DE PROCESO 3 | E16: MIN | F16: 4
B18: 9002 | C18: PRODUCTO B
C19: 1001 | D19: MATERIA PRIMA A | E19: KGS | F19: =F4*0.84 -> 0.84 | G19: =VLOOKUP(C19,COMPRAS!B:E,4,0) -> 100 | H19: =F19*G19 -> 84
C20: 1002 | D20: MATERIA PRIMA B | E20: KGS | F20: =F5*0.84 -> 0.42 | G20: =VLOOKUP(C20,COMPRAS!B:E,4,0) -> 55 | H20: =F20*G20 -> 23.1
C21: 1003 | D21: MATERIA PRIMA C | E21: KGS | F21: =F6*0.84 -> 0.2688 | G21: =VLOOKUP(C21,COMPRAS!B:E,4,0) -> 20 | H21: =F21*G21 -> 5.376
C22: 1004 | D22: MATERIA PRIMA D | E22: KGS | F22: =F7*0.84 -> 1.68 | G22: =VLOOKUP(C22,COMPRAS!B:E,4,0) -> 34 | H22: =F22*G22 -> 57.12
C23: 1005 | D23: MATERIA PRIMA E | E23: KGS | F23: =F8*0.84 -> 0.5628 | G23: =VLOOKUP(C23,COMPRAS!B:E,4,0) -> 15 | H23: =F23*G23 -> 8.442
C24: 1006 | D24: MATERIA PRIMA F | E24: KGS | F24: =F9*0.84 -> 0.168 | G24: =VLOOKUP(C24,COMPRAS!B:E,4,0) -> 67 | H24: =F24*G24 -> 11.256
C25: 1007 | D25: MATERIA PRIMA G | E25: KGS | F25: =F10*0.84 -> 0.084 | G25: =VLOOKUP(C25,COMPRAS!B:E,4,0) -> 22 | H25: =F25*G25 -> 1.848
C26: 1008 | D26: MATERIA PRIMA H | E26: KGS | F26: =F11*0.84 -> 0.672 | G26: =VLOOKUP(C26,COMPRAS!B:E,4,0) -> 35 | H26: =F26*G26 -> 23.52
C27: 1009 | D27: MATERIA PRIMA I | E27: PZA | F27: 1 | G27: =VLOOKUP(C27,COMPRAS!B:E,4,0) -> 15 | H27: =F27*G27 -> 15
C28: 1010 | D28: MATERIA PRIMA J | E28: PZA | F28: 1 | G28: =VLOOKUP(C28,COMPRAS!B:E,4,0) -> 10 | H28: =F28*G28 -> 10
C29: WC1 1P | D29: TIEMPO DE PROCESO 1 | E29: MIN | F29: =F14*1.1 -> 5.5
C30: WC1 2P | D30: TIEMPO DE PROCESO 2 | E30: MIN | F30: =F15*1.1 -> 7.7
C31: WC1 3P | D31: TIEMPO DE PROCESO 3 | E31: MIN | F31: =F16*1.1 -> 4.4
B33: 9003 | C33: PRODUCTO C
C34: 1001 | D34: MATERIA PRIMA A | E34: KGS | F34: =F4*1.05 -> 1.05 | G34: =VLOOKUP(C34,COMPRAS!B:E,4,0) -> 100 | H34: =F34*G34 -> 105
C35: 1002 | D35: MATERIA PRIMA B | E35: KGS | F35: =F5*1.05 -> 0.525 | G35: =VLOOKUP(C35,COMPRAS!B:E,4,0) -> 55 | H35: =F35*G35 -> 28.875
C36: 1003 | D36: MATERIA PRIMA C | E36: KGS | F36: =F6*1.05 -> 0.336 | G36: =VLOOKUP(C36,COMPRAS!B:E,4,0) -> 20 | H36: =F36*G36 -> 6.72
C37: 1004 | D37: MATERIA PRIMA D | E37: KGS | F37: =F7*1.05 -> 2.1 | G37: =VLOOKUP(C37,COMPRAS!B:E,4,0) -> 34 | H37: =F37*G37 -> 71.4
C38: 1005 | D38: MATERIA PRIMA E | E38: KGS | F38: =F8*1.05 -> 0.7035 | G38: =VLOOKUP(C38,COMPRAS!B:E,4,0) -> 15 | H38: =F38*G38 -> 10.5525
C39: 1006 | D39: MATERIA PRIMA F | E39: KGS | F39: =F9*1.05 -> 0.21 | G39: =VLOOKUP(C39,COMPRAS!B:E,4,0) -> 67 | H39: =F39*G39 -> 14.07
C40: 1007 | D40: MATERIA PRIMA G | E40: KGS | F40: =F10*1.05 -> 0.105 | G40: =VLOOKUP(C40,COMPRAS!B:E,4,0) -> 22 | H40: =F40*G40 -> 2.31
C41: 1008 | D41: MATERIA PRIMA H | E41: KGS | F41: =F11*1.05 -> 0.84 | G41: =VLOOKUP(C41,COMPRAS!B:E,4,0) -> 35 | H41: =F41*G41 -> 29.4
C42: 1009 | D42: MATERIA PRIMA I | E42: PZA | F42: 1 | G42: =VLOOKUP(C42,COMPRAS!B:E,4,0) -> 15 | H42: =F42*G42 -> 15
C43: 1010 | D43: MATERIA PRIMA J | E43: PZA | F43: 1 | G43: =VLOOKUP(C43,COMPRAS!B:E,4,0) -> 10 | H43: =F43*G43 -> 10
...

Sheet COMPRAS
B3: CODIGO MP | C3: DESCRIPCION | D3: UM | E3: COSTO STD | K3: COSTO ESTÁNDAR DE MATERIAS PRIMAS
B4: 1001 | C4: MATERIA PRIMA A | D4: KGS | E4: 100 | J4: A) | K4: COSTO DE MATERIAL PUESTO EN PLANTA
B5: 1002 | C5: MATERIA PRIMA B | D5: KGS | E5: 55
B6: 1003 | C6: MATERIA PRIMA C | D6: KGS | E6: 20
B7: 1004 | C7: MATERIA PRIMA D | D7: KGS | E7: 34
B8: 1005 | C8: MATERIA PRIMA E | D8: KGS | E8: 15
B9: 1006 | C9: MATERIA PRIMA F | D9: KGS | E9: 67
B10: 1007 | C10: MATERIA PRIMA G | D10: KGS | E10: 22
B11: 1008 | C11: MATERIA PRIMA H | D11: KGS | E11: 35
B12: 1009 | C12: MATERIA PRIMA I | D12: PZA | E12: 15
B13: 1010 | C13: MATERIA PRIMA J | D13: PZA | E13: 10
D18: COMPRADOS | G18: STD | H18: REAL | I18: VAR | K18: STD | L18: REAL | M18: VAR
B19: 1001 | C19: MATERIA PRIMA A | D19: KGS | E19: ='PROD REAL'!F60 -> 69650 | G19: =E4 -> 100 | H19: 105 | I19: =H19-G19 -> 5 | K19: =E19*G19 -> 6965000 | L19: =E19*H19 -> 7313250 | M19: =L19-K19 -> 348250
B20: 1002 | C20: MATERIA PRIMA B | D20: KGS | E20: ='PROD REAL'!F61 -> 34825 | G20: =E5 -> 55 | H20: 56 | I20: =H20-G20 -> 1 | K20: =E20*G20 -> 1915375 | L20: =E20*H20 -> 1950200 | M20: =L20-K20 -> 34825
B21: 1003 | C21: MATERIA PRIMA C | D21: KGS | E21: ='PROD REAL'!F62 -> 22288 | G21: =E6 -> 20 | H21: 21 | I21: =H21-G21 -> 1 | K21: =E21*G21 -> 445760 | L21: =E21*H21 -> 468048 | M21: =L21-K21 -> 22288
B22: 1004 | C22: MATERIA PRIMA D | D22: KGS | E22: ='PROD REAL'!F63 -> 139300 | G22: =E7 -> 34 | H22: 30 | I22: =H22-G22 -> -4 | K22: =E22*G22 -> 4736200 | L22: =E22*H22 -> 4179000 | M22: =L22-K22 -> -557200
B23: 1005 | C23: MATERIA PRIMA E | D23: KGS | E23: ='PROD REAL'!F64 -> 46665.5 | G23: =E8 -> 15 | H23: 15 | I23: =H23-G23 -> 0 | K23: =E23*G23 -> 699982.5 | L23: =E23*H23 -> 699982.5 | M23: =L23-K23 -> 0
B24: 1006 | C24: MATERIA PRIMA F | D24: KGS | E24: ='PROD REAL'!F65 -> 13930 | G24: =E9 -> 67 | H24: 67 | I24: =H24-G24 -> 0 | K24: =E24*G24 -> 933310 | L24: =E24*H24 -> 933310 | M24: =L24-K24 -> 0
B25: 1007 | C25: MATERIA PRIMA G | D25: KGS | E25: ='PROD REAL'!F66 -> 6965 | G25: =E10 -> 22 | H25: 18 | I25: =H25-G25 -> -4 | K25: =E25*G25 -> 153230 | L25: =E25*H25 -> 125370 | M25: =L25-K25 -> -27860
B26: 1008 | C26: MATERIA PRIMA H | D26: KGS | E26: ='PROD REAL'!F67 -> 55720 | G26: =E11 -> 35 | H26: 35.5 | I26: =H26-G26 -> 0.5 | K26: =E26*G26 -> 1950200 | L26: =E26*H26 -> 1978060 | M26: =L26-K26 -> 27860
B27: 1009 | C27: MATERIA PRIMA I | D27: PZA | E27: ='PROD REAL'!F68 -> 70000 | G27: =E12 -> 15 | H27: 20 | I27: =H27-G27 -> 5 | K27: =E27*G27 -> 1050000 | L27: =E27*H27 -> 1400000 | M27: =L27-K27 -> 350000
B28: 1010 | C28: MATERIA PRIMA J | D28: PZA | E28: ='PROD REAL'!F69 -> 70000 | G28: =E13 -> 10 | H28: 12 | I28: =H28-G28 -> 2 | K28: =E28*G28 -> 700000 | L28: =E28*H28 -> 840000 | M28: =L28-K28 -> 140000
K29: =SUM(K19:K28) -> 19549058 | L29: =SUM(L19:L28) -> 19887220 | M29: =SUM(M19:M28) -> 338163

Sheet REC HUMANOS
G2: 1.0493
B3: CC | C3: DESCRIPCION DEL CC | D3: NOMBRE | E3: PUESTO | F3: SUELDO DIARIO | G3: SUELDO INTEGRADO | J3: PRESTACIONES
B4: 100 | C4: PROCESO CONVERSION 1 | D4: JUAN PEREZ | E4: MECANICO | F4: 315 | G4: =F4*($G$2) -> 330.5295 | J4: AGUINALDO | K4: 15 | L4: DIAS | M4: CONFORME A LEY
B5: 100 | C5: PROCESO CONVERSION 1 | D5: EDGAR X | E5: MECANICO | F5: 315 | G5: =F5*($G$2) -> 330.5295 | J5: VACACIONES | K5: 12 | L5: DIAS | M5: CONFORME A LEY
B6: 100 | C6: PROCESO CONVERSION 1 | D6: SONIA Y | E6: MECANICO | F6: 315 | G6: =F6*($G$2) -> 330.5295 | J6: PRIMA VACACIONAL | K6: 0.25 | M6: CONFORME A LEY
B7: 100 | C7: PROCESO CONVERSION 1 | D7: SOFIA B | E7: MECANICO | F7: 315 | G7: =F7*($G$2) -> 330.5295
B8: 100 | C8: PROCESO CONVERSION 1 | D8: PEDRO X | E8: MECANICO | F8: 315 | G8: =F8*($G$2) -> 330.5295
B9: 100 | C9: PROCESO CONVERSION 1 | D9: JOEL Z | E9: MECANICO | F9: 315 | G9: =F9*($G$2) -> 330.5295 | J9: IMSS | K9: 0.2
B10: 100 | C10: PROCESO CONVERSION 1 | D10: CARLOS F | E10: MECANICO | F10: 315 | G10: =F10*($G$2) -> 330.5295 | J10: SAR | K10: 0.045
B11: 100 | C11: PROCESO CONVERSION 1 | D11: MANUEL R | E11: MECANICO | F11: 315 | G11: =F11*($G$2) -> 330.5295 | J11: INFONAVIT | K11: 0.05
B12: 100 | C12: PROCESO CONVERSION 1 | D12: ERICK J | E12: SUPERVISOR | F12: 500 | G12: =F12*($G$2) -> 524.65
B13: 110 | C13: PROCESO CONVERSION 2 | D13: VERONICA L | E13: MECANICO | F13: 315 | G13: =F13*($G$2) -> 330.5295
B14: 110 | C14: PROCESO CONVERSION 2 | D14: ALEJANDRO H | E14: MECANICO | F14: 315 | G14: =F14*($G$2) -> 330.5295 | J14: IMPUESTO ESTATAL | K14: 0.03
B15: 110 | C15: PROCESO CONVERSION 2 | D15: JANETTE M | E15: MECANICO | F15: 315 | G15: =F15*($G$2) -> 330.5295
B16: 110 | C16: PROCESO CONVERSION 2 | D16: ALEXA T | E16: MECANICO | F16: 315 | G16: =F16*($G$2) -> 330.5295
B17: 110 | C17: PROCESO CONVERSION 2 | D17: BERENICE J | E17: MECANICO | F17: 315 | G17: =F17*($G$2) -> 330.5295
B18: 110 | C18: PROCESO CONVERSION 2 | D18: ALMA G | E18: MECANICO | F18: 315 | G18: =F18*($G$2) -> 330.5295
B19: 110 | C19: PROCESO CONVERSION 2 | D19: FRANCISCO R | E19: SUPERVISOR | F19: 500 | G19: =F19*($G$2) -> 524.65
B20: 120 | C20: PROCESO CONVERSION 3 | D20: RAFAEL H | E20: MECANICO | F20: 315 | G20: =F20*($G$2) -> 330.5295
B21: 120 | C21: PROCESO CONVERSION 3 | D21: MANUEL O | E21: MECANICO | F21: 315 | G21: =F21*($G$2) -> 330.5295
B22: 120 | C22: PROCESO CONVERSION 3 | D22: DAVID E | E22: MECANICO | F22: 315 | G22: =F22*($G$2) -> 330.5295
B23: 120 | C23: PROCESO CONVERSION 3 | D23: OSCAR J | E23: MECANICO | F23: 315 | G23: =F23*($G$2) -> 330.5295
B24: 120 | C24: PROCESO CONVERSION 3 | D24: DARIO C | E24: MECANICO | F24: 315 | G24: =F24*($G$2) -> 330.5295
B25: 120 | C25: PROCESO CONVERSION 3 | D25: ALFREDO X | E25: MECANICO | F25: 315 | G25: =F25*($G$2) -> 330.5295
B26: 120 | C26: PROCESO CONVERSION 3 | D26: DANIEL G | E26: SUPERVISOR | F26: 500 | G26: =F26*($G$2) -> 524.65
... B40: 320 | C40: GERENCIA REGIONAL CENTRO | D40: LUIS A | E40: KAM | F40: 550 | G40: =F40*($G$2) -> 577.115

Sheet CONTABILIDAD & COSTOS
C3: CC | D3: DESCRIPCION DEL CC | G3: CUENTAS CONTABLES
B4: PRODUCTIVOS | C4: 100 | D4: PROCESO CONVERSION 1 | G4: 1001001 | H4: Salarios
B5: PRODUCTIVOS | C5: 110 | D5: PROCESO CONVERSION 2 | G5: 1001002 | H5: Tiempo extra
B6: PRODUCTIVOS | C6: 120 | D6: PROCESO CONVERSION 3 | G6: 1001003 | H6: Vacaciones
B7: SERVICIOS | C7: 150 | D7: ALMACEN DE MP | G7: 1001004 | H7: Prima vacacional
B8: SERVICIOS | C8: 160 | D8: INGENIERIA PLANTA | G8: 1001005 | H8: Aguinaldo
B9: SERVICIOS | C9: 170 | D9: CALIDAD | G9: 1001006 | H9: Imss
G10: 1001007 | H10: SAR
B11: ADMINISTRACION | C11: 200 | D11: GERENCIA GENERAL | G11: 1001008 | H11: Infonavit
B12: ADMINISTRACION | C12: 210 | D12: CONTABILIDAD | G12: 1001009 | H12: Impuesto Estatal
B13: ADMINISTRACION | C13: 220 | D13: RECURSOS HUMANOS | G13: 1002001 | H13: Energia Electrica
G14: 1002002 | H14: Agua
B15: VENTAS | C15: 300 | D15: GERENCIA COMERCIAL | G15: 1002003 | H15: Gas
B16: VENTAS | C16: 310 | D16: GERENCIA REGIONAL NORTE | G16: 1002004 | H16: Mantenimientos
B17: VENTAS | C17: 320 | D17: GERENCIA REGIONAL CENTRO | G17: 1002005 | H17: Refacciones
G18: 1002006 | H18: Gastos Indirectos
G19: 1003001 | H19: Sueldos
G20: 1003002 | H20: Tiempo extra
G21: 1003003 | H21: Vacaciones
G22: 1003004 | H22: Prima vacacional
G23: 1003005 | H23: Aguinaldo
G24: 1003006 | H24: Imss
G25: 1003007 | H25: SAR
G26: 1003008 | H26: Infonavit
G27: 1003009 | H27: Impuesto Estatal
G28: 1003101 | H28: Depreciaciones
G29: 1003102 | H29: Amortizaciones
... G31: 1003104 | H31: Rentas
G33: PRORRETEOS | J33: MENSUAL
G34: 1003101 | H34: Depreciaciones | J34: 75000
G35: 100 | H35: PROCESO CONVERSION 1 | I35: 0.2 | J35: =I35*$J$34 -> 15000
G36: 110 | H36: PROCESO CONVERSION 2 | I36: 0.2 | J36: =I36*$J$34 -> 15000
G37: 120 | H37: PROCESO CONVERSION 3 | I37: 0.2 | J37: =I37*$J$34 -> 15000
G38: 200 | H38: GERENCIA GENERAL | I38: 0.05 | J38: =I38*$J$34 -> 3750
G39: 210 | H39: CONTABILIDAD | I39: 0.1 | J39: =I39*$J$34 -> 7500
G40: 220 | H40: RECURSOS HUMANOS | I40: 0.1 | J40: =I40*$J$34 -> 7500
G41: 300 | H41: GERENCIA COMERCIAL | I41: 0.05 | J41: =I41*$J$34 -> 3750
G42: 310 | H42: GERENCIA REGIONAL NORTE | I42: 0.05 | J42: =I42*$J$34 -> 3750
G43: 320 | H43: GERENCIA REGIONAL CENTRO | I43: 0.05 | J43: =I43*$J$34 -> 3750
I44: =SUM(I35:I43) -> 1
...

Sheet COSTOS (Calculo)
G2: 31 | H2: 28 | I2: 31 | J2: 30 | K2: 31 | L2: 30 | M2: 31 | N2: 31 | O2: 30 | P2: 31 | Q2: 30 | R2: 31
B3: CC | C3: Descripcion CC | D3: Clasificacion | E3: Cuenta | F3: Descrpicion Cuenta | G3: ENERO | H3: FEBRERO | I3: MARZO | J3: ABRIL | K3: MAYO | L3: JUNIO | M3: JULIO | N3: AGOSTO | O3: SEPTIEMBRE | P3: OCTUBRE | Q3: NOVIEMBRE | R3: DICIEMBRE | S3: TOTAL
B4: 100 | C4: PROCESO CONVERSION 1 | D4: MANO DE OBRA DIRECTA | E4: 1001001 | F4: Salarios | G4: =SUM('REC HUMANOS'!F4:F11)*G2 -> 78120 | H4: =$G$4/$G$2*H2 -> 70560 | I4: =$G$4/$G$2*I2 -> 78120 | J4: =$G$4/$G$2*J2 -> 75600 | K4: =$G$4/$G$2*K2 -> 78120 | L4: =$G$4/$G$2*L2 -> 75600 | M4: =$G$4/$G$2*M2 -> 78120 | N4: =$G$4/$G$2*N2 -> 78120 | O4: =$G$4/$G$2*O2 -> 75600 | ... R4: =$G$4/$G$2*R2 -> 78120 | S4: =SUM(G4:R4) -> 919800
B5: 100 | C5: PROCESO CONVERSION 1 | D5: MANO DE OBRA DIRECTA | E5: 1001002 | F5: Tiempo extra | S5: =SUM(G5:R5) -> 0
B6: 100 | C6: PROCESO CONVERSION 1 | D6: MANO DE OBRA DIRECTA | E6: 1001003 | F6: Vacaciones | S6: =SUM(G6:R6) -> 0
B7: 100 | C7: PROCESO CONVERSION 1 | D7: MANO DE OBRA DIRECTA | E7: 1001004 | F7: Prima vacacional | G7: =(((G4/G2)*15)/12)*0.25 -> 787.5 | H7: =(((H4/H2)*15)/12)*0.25 -> 787.5 | I7: =(((I4/I2)*15)/12)*0.25 -> 787.5 | J7: =(((J4/J2)*15)/12)*0.25 -> 787.5 | K7: =(((K4/K2)*15)/12)*0.25 -> 787.5 | L7: =(((L4/L2)*15)/12)*0.25 -> 787.5 | M7: =(((M4/M2)*15)/12)*0.25 -> 787.5 | N7: =(((N4/N2)*15)/12)*0.25 -> 787.5 | ... R7: =(((R4/R2)*15)/12)*0.25 -> 787.5 | S7: =SUM(G7:R7) -> 9450
B8: 100 | C8: PROCESO CONVERSION 1 | D8: MANO DE OBRA DIRECTA | E8: 1001005 | F8: Aguinaldo | G8: =(((G4/G2)*15)/12) -> 3150 | H8: =(((H4/H2)*15)/12) -> 3150 | I8: =(((I4/I2)*15)/12) -> 3150 | J8: =(((J4/J2)*15)/12) -> 3150 | K8: =(((K4/K2)*15)/12) -> 3150 | L8: =(((L4/L2)*15)/12) -> 3150 | M8: =(((M4/M2)*15)/12) -> 3150 | N8: =(((N4/N2)*15)/12) -> 3150 | ... R8: =(((R4/R2)*15)/12) -> 3150 | S8: =SUM(G8:R8) -> 37800
B9: 100 | C9: PROCESO CONVERSION 1 | D9: MANO DE OBRA DIRECTA | E9: 1001006 | F9: Imss | G9: =(G4*'REC HUMANOS'!$G$2)*'REC HUMANOS'!$K$9 -> 16394.263 | H9: =(H4*'REC HUMANOS'!$G$2)*'REC HUMANOS'!$K$9 -> 14807.722 | I9: =(I4*'REC HUMANOS'!$G$2)*'REC HUMANOS'!$K$9 -> 16394.263 | J9: =(J4*'REC HUMANOS'!$G$2)*'REC HUMANOS'!$K$9 -> 15865.416 | K9: =(K4*'REC HUMANOS'!$G$2)*'REC HUMANOS'!$K$9 -> 16394.263 | L9: =(L4*'REC HUMANOS'!$G$2)*'REC HUMANOS'!$K$9 -> 15865.416 | M9: =(M4*'REC HUMANOS'!$G$2)*'REC HUMANOS'!$K$9 -> 16394.263 | N9: =(N4*'REC HUMANOS'!$G$2)*'REC HUMANOS'!$K$9 -> 16394.263 | ... R9: =(R4*'REC HUMANOS'!$G$2)*'REC HUMANOS'!$K$9 -> 16394.263 | S9: =SUM(G9:R9) -> 193029.23
B10: 100 | C10: PROCESO CONVERSION 1 | D10: MANO DE OBRA DIRECTA | E10: 1001007 | F10: SAR | G10: =(G4*'REC HUMANOS'!$G$2)*'REC HUMANOS'!$K$10 -> 3688.7092 | H10: =(H4*'REC HUMANOS'!$G$2)*'REC HUMANOS'!$K$10 -> 3331.7374 | I10: =(I4*'REC HUMANOS'!$G$2)*'REC HUMANOS'!$K$10 -> 3688.7092 | J10: =(J4*'REC HUMANOS'!$G$2)*'REC HUMANOS'!$K$10 -> 3569.7186 | K10: =(K4*'REC HUMANOS'!$G$2)*'REC HUMANOS'!$K$10 -> 3688.7092 | L10: =(L4*'REC HUMANOS'!$G$2)*'REC HUMANOS'!$K$10 -> 3569.7186 | M10: =(M4*'REC HUMANOS'!$G$2)*'REC HUMANOS'!$K$10 -> 3688.7092 | N10: =(N4*'REC HUMANOS'!$G$2)*'REC HUMANOS'!$K$10 -> 3688.7092 | ... R10: =(R4*'REC HUMANOS'!$G$2)*'REC HUMANOS'!$K$10 -> 3688.7092 | S10: =SUM(G10:R10) -> 43431.576
B11: 100 | C11: PROCESO CONVERSION 1 | D11: MANO DE OBRA DIRECTA | E11: 1001008 | F11: Infonavit | G11: =(G4*'REC HUMANOS'!$G$2)*'REC HUMANOS'!$K$11 -> 4098.5658 | H11: =(H4*'REC HUMANOS'!$G$2)*'REC HUMANOS'!$K$11 -> 3701.9304 | I11: =(I4*'REC HUMANOS'!$G$2)*'REC HUMANOS'!$K$11 -> 4098.5658 | J11: =(J4*'REC HUMANOS'!$G$2)*'REC HUMANOS'!$K$11 -> 3966.354 | K11: =(K4*'REC HUMANOS'!$G$2)*'REC HUMANOS'!$K$11 -> 4098.5658 | L11: =(L4*'REC HUMANOS'!$G$2)*'REC HUMANOS'!$K$11 -> 3966.354 | M11: =(M4*'REC HUMANOS'!$G$2)*'REC HUMANOS'!$K$11 -> 4098.5658 | N11: =(N4*'REC HUMANOS'!$G$2)*'REC HUMANOS'!$K$11 -> 4098.5658 | ... R11: =(R4*'REC HUMANOS'!$G$2)*'REC HUMANOS'!$K$11 -> 4098.5658 | S11: =SUM(G11:R11) -> 48257.307
B12: 100 | C12: PROCESO CONVERSION 1 | D12: MANO DE OBRA DIRECTA | E12: 1001009 | F12: Impuesto Estatal | G12: =(G4*'REC HUMANOS'!$G$2)*'REC HUMANOS'!$K$14 -> 2459.1395 | H12: =(H4*'REC HUMANOS'!$G$2)*'REC HUMANOS'!$K$14 -> 2221.1582 | I12: =(I4*'REC HUMANOS'!$G$2)*'REC HUMANOS'!$K$14 -> 2459.1395 | J12: =(J4*'REC HUMANOS'!$G$2)*'REC HUMANOS'!$K$14 -> 2379.8124 | K12: =(K4*'REC HUMANOS'!$G$2)*'REC HUMANOS'!$K$14 -> 2459.1395 | L12: =(L4*'REC HUMANOS'!$G$2)*'REC HUMANOS'!$K$14 -> 2379.8124 | M12: =(M4*'REC HUMANOS'!$G$2)*'REC HUMANOS'!$K$14 -> 2459.1395 | N12: =(N4*'REC HUMANOS'!$G$2)*'REC HUMANOS'!$K$14 -> 2459.1395 | ... R12: =(R4*'REC HUMANOS'!$G$2)*'REC HUMANOS'!$K$14 -> 2459.1395 | S12: =SUM(G12:R12) -> 28954.384
B13: 100 | C13: PROCESO CONVERSION 1 | D13: GASTOS VARIABLES | E13: 1002001 | F13: Energia Electrica | G13: 40000 | H13: 40000 | I13: 40000 | J13: 40000 | K13: 40000 | L13: 40000 | M13: 40000 | N13: 40000 | O13: 40000 | P13: 40000 | Q13: 40000 | R13: 40000 | S13: =SUM(G13:R13) -> 480000
B14: 100 | C14: PROCESO CONVERSION 1 | D14: GASTOS VARIABLES | E14: 1002002 | F14: Agua | G14: 12000 | H14: 12000 | I14: 12000 | J14: 12000 | K14: 12000 | L14: 12000 | M14: 12000 | N14: 12000 | O14: 12000 | P14: 12000 | Q14: 12000 | R14: 12000 | S14: =SUM(G14:R14) -> 144000
B15: 100 | C15: PROCESO CONVERSION 1 | D15: GASTOS VARIABLES | E15: 1002003 | F15: Gas | G15: 4500 | H15: 4500 | I15: 4500 | J15: 4500 | K15: 4500 | L15: 4500 | M15: 4500 | N15: 4500 | O15: 4500 | P15: 4500 | Q15: 4500 | R15: 4500 | S15: =SUM(G15:R15) -> 54000
B16: 100 | C16: PROCESO CONVERSION 1 | D16: GASTOS VARIABLES | E16: 1002004 | F16: Mantenimientos | G16: 1000 | H16: 1000 | I16: 1000 | J16: 1000 | K16: 1000 | L16: 1000 | M16: 1000 | N16: 1000 | O16: 1000 | P16: 1000 | Q16: 1000 | R16: 1000 | S16: =SUM(G16:R16) -> 12000
B17: 100 | C17: PROCESO CONVERSION 1 | D17: GASTOS VARIABLES | E17: 1002005 | F17: Refacciones | G17: 1500 | H17: 1500 | I17: 1500 | J17: 1500 | K17: 1500 | L17: 1500 | M17: 1500 | N17: 1500 | O17: 1500 | P17: 1500 | Q17: 1500 | R17: 1500 | S17: =SUM(G17:R17) -> 18000
B18: 100 | C18: PROCESO CONVERSION 1 | D18: GASTOS VARIABLES | E18: 1002006 | F18: Gastos Indirectos | G18: 1000 | H18: 1000 | I18: 1000 | J18: 1000 | K18: 1000 | L18: 1000 | M18: 1000 | N18: 1000 | O18: 1000 | P18: 1000 | Q18: 1000 | R18: 1000 | S18: =SUM(G18:R18) -> 12000
B19: 100 | C19: PROCESO CONVERSION 1 | D19: GASTOS FIJOS | E19: 1003001 | F19: Sueldos | G19: ='REC HUMANOS'!F12*30 -> 15000 | H19: =G19 -> 15000 | I19: =H19 -> 15000 | J19: =I19 -> 15000 | K19: =J19 -> 15000 | L19: =K19 -> 15000 | M19: =L19 -> 15000 | N19: =M19 -> 15000 | O19: =N19 -> 15000 | ... R19: =Q19 -> 15000 | S19: =SUM(G19:R19) -> 180000
B20: 100 | C20: PROCESO CONVERSION 1 | D20: GASTOS FIJOS | E20: 1003002 | F20: Tiempo extra | S20: =SUM(G20:R20) -> 0
B21: 100 | C21: PROCESO CONVERSION 1 | D21: GASTOS FIJOS | E21: 1003003 | F21: Vacaciones | S21: =SUM(G21:R21) -> 0
B22: 100 | C22: PROCESO CONVERSION 1 | D22: GASTOS FIJOS | E22: 1003004 | F22: Prima vacacional | G22: =(((G19/G2)*15)/12)*'REC HUMANOS'!$K$6 -> 151.20968 | H22: =(((H19/H2)*15)/12)*'REC HUMANOS'!$K$6 -> 167.41071 | I22: =(((I19/I2)*15)/12)*'REC HUMANOS'!$K$6 -> 151.20968 | J22: =(((J19/J2)*15)/12)*'REC HUMANOS'!$K$6 -> 156.25 | K22: =(((K19/K2)*15)/12)*'REC HUMANOS'!$K$6 -> 151.20968 | L22: =(((L19/L2)*15)/12)*'REC HUMANOS'!$K$6 -> 156.25 | M22: =(((M19/M2)*15)/12)*'REC HUMANOS'!$K$6 -> 151.20968 | N22: =(((N19/N2)*15)/12)*'REC HUMANOS'!$K$6 -> 151.20968 | ... R22: =(((R19/R2)*15)/12)*'REC HUMANOS'!$K$6 -> 151.20968 | S22: =SUM(G22:R22) -> 1850.8785
B23: 100 | C23: PROCESO CONVERSION 1 | D23: GASTOS FIJOS | E23: 1003005 | F23: Aguinaldo | G23: =(((G19/G2)*'REC HUMANOS'!$K$4/12)) -> 604.83871 | H23: =(((H19/H2)*'REC HUMANOS'!$K$4/12)) -> 669.64286 | I23: =(((I19/I2)*'REC HUMANOS'!$K$4/12)) -> 604.83871 | J23: =(((J19/J2)*'REC HUMANOS'!$K$4/12)) -> 625 | K23: =(((K19/K2)*'REC HUMANOS'!$K$4/12)) -> 604.83871 | L23: =(((L19/L2)*'REC HUMANOS'!$K$4/12)) -> 625 | M23: =(((M19/M2)*'REC HUMANOS'!$K$4/12)) -> 604.83871 | N23: =(((N19/N2)*'REC HUMANOS'!$K$4/12)) -> 604.83871 | ... R23: =(((R19/R2)*'REC HUMANOS'!$K$4/12)) -> 604.83871 | S23: =SUM(G23:R23) -> 7403.5138
B24: 100 | C24: PROCESO CONVERSION 1 | D24: GASTOS FIJOS | E24: 1003006 | F24: Imss | G24: =(G19*'REC HUMANOS'!$G$2)*'REC HUMANOS'!$K$9 -> 3147.9 | H24: =(H19*'REC HUMANOS'!$G$2)*'REC HUMANOS'!$K$9 -> 3147.9 | I24: =(I19*'REC HUMANOS'!$G$2)*'REC HUMANOS'!$K$9 -> 3147.9 | J24: =(J19*'REC HUMANOS'!$G$2)*'REC HUMANOS'!$K$9 -> 3147.9 | K24: =(K19*'REC HUMANOS'!$G$2)*'REC HUMANOS'!$K$9 -> 3147.9 | L24: =(L19*'REC HUMANOS'!$G$2)*'REC HUMANOS'!$K$9 -> 3147.9 | M24: =(M19*'REC HUMANOS'!$G$2)*'REC HUMANOS'!$K$9 -> 3147.9 | N24: =(N19*'REC HUMANOS'!$G$2)*'REC HUMANOS'!$K$9 -> 3147.9 | ... R24: =(R19*'REC HUMANOS'!$G$2)*'REC HUMANOS'!$K$9 -> 3147.9 | S24: =SUM(G24:R24) -> 37774.8
B25: 100 | C25: PROCESO CONVERSION 1 | D25: GASTOS FIJOS | E25: 1003007 | F25: SAR | G25: =(G19*'REC HUMANOS'!$G$2)*'REC HUMANOS'!$K$10 -> 708.2775 | H25: =(H19*'REC HUMANOS'!$G$2)*'REC HUMANOS'!$K$10 -> 708.2775 | I25: =(I19*'REC HUMANOS'!$G$2)*'REC HUMANOS'!$K$10 -> 708.2775 | J25: =(J19*'REC HUMANOS'!$G$2)*'REC HUMANOS'!$K$10 -> 708.2775 | K25: =(K19*'REC HUMANOS'!$G$2)*'REC HUMANOS'!$K$10 -> 708.2775 | L25: =(L19*'REC HUMANOS'!$G$2)*'REC HUMANOS'!$K$10 -> 708.2775 | M25: =(M19*'REC HUMANOS'!$G$2)*'REC HUMANOS'!$K$10 -> 708.2775 | N25: =(N19*'REC HUMANOS'!$G$2)*'REC HUMANOS'!$K$10 -> 708.2775 | ... R25: =(R19*'REC HUMANOS'!$G$2)*'REC HUMANOS'!$K$10 -> 708.2775 | S25: =SUM(G25:R25) -> 8499.33
B26: 100 | C26: PROCESO CONVERSION 1 | D26: GASTOS FIJOS | E26: 1003008 | F26: Infonavit | G26: =(G19*'REC HUMANOS'!$G$2)*'REC HUMANOS'!$K$11 -> 786.975 | H26: =(H19*'REC HUMANOS'!$G$2)*'REC HUMANOS'!$K$11 -> 786.975 | I26: =(I19*'REC HUMANOS'!$G$2)*'REC HUMANOS'!$K$11 -> 786.975 | J26: =(J19*'REC HUMANOS'!$G$2)*'REC HUMANOS'!$K$11 -> 786.975 | K26: =(K19*'REC HUMANOS'!$G$2)*'REC HUMANOS'!$K$11 -> 786.975 | L26: =(L19*'REC HUMANOS'!$G$2)*'REC HUMANOS'!$K$11 -> 786.975 | M26: =(M19*'REC HUMANOS'!$G$2)*'REC HUMANOS'!$K$11 -> 786.975 | N26: =(N19*'REC HUMANOS'!$G$2)*'REC HUMANOS'!$K$11 -> 786.975 | ... R26: =(R19*'REC HUMANOS'!$G$2)*'REC HUMANOS'!$K$11 -> 786.975 | S26: =SUM(G26:R26) -> 9443.7
B27: 100 | C27: PROCESO CONVERSION 1 | D27: GASTOS FIJOS | E27: 1003009 | F27: Impuesto Estatal | G27: =(G19*'REC HUMANOS'!$G$2)*'REC HUMANOS'!$K$14 -> 472.185 | H27: =(H19*'REC HUMANOS'!$G$2)*'REC HUMANOS'!$K$14 -> 472.185 | I27: =(I19*'REC HUMANOS'!$G$2)*'REC HUMANOS'!$K$14 -> 472.185 | J27: =(J19*'REC HUMANOS'!$G$2)*'REC HUMANOS'!$K$14 -> 472.185 | K27: =(K19*'REC HUMANOS'!$G$2)*'REC HUMANOS'!$K$14 -> 472.185 | L27: =(L19*'REC HUMANOS'!$G$2)*'REC HUMANOS'!$K$14 -> 472.185 | M27: =(M19*'REC HUMANOS'!$G$2)*'REC HUMANOS'!$K$14 -> 472.185 | N27: =(N19*'REC HUMANOS'!$G$2)*'REC HUMANOS'!$K$14 -> 472.185 | ... R27: =(R19*'REC HUMANOS'!$G$2)*'REC HUMANOS'!$K$14 -> 472.185 | S27: =SUM(G27:R27) -> 5666.22
B28: 100 | C28: PROCESO CONVERSION 1 | D28: GASTOS FIJOS | E28: 1003101 | F28: Depreciaciones | G28: ='CONTABILIDAD & COSTOS'!$J$35 -> 15000 | H28: ='CONTABILIDAD & COSTOS'!$J$35 -> 15000 | I28: ='CONTABILIDAD & COSTOS'!$J$35 -> 15000 | J28: ='CONTABILIDAD & COSTOS'!$J$35 -> 15000 | K28: ='CONTABILIDAD & COSTOS'!$J$35 -> 15000 | L28: ='CONTABILIDAD & COSTOS'!$J$35 -> 15000 | M28: ='CONTABILIDAD & COSTOS'!$J$35 -> 15000 | N28: ='CONTABILIDAD & COSTOS'!$J$35 -> 15000 | ... R28: ='CONTABILIDAD & COSTOS'!$J$35 -> 15000 | S28: =SUM(G28:R28) -> 180000
B29: 100 | C29: PROCESO CONVERSION 1 | D29: GASTOS FIJOS | E29: 1003102 | F29: Amortizaciones | G29: ='CONTABILIDAD & COSTOS'!$J$47 -> 250 | H29: ='CONTABILIDAD & COSTOS'!$J$47 -> 250 | I29: ='CONTABILIDAD & COSTOS'!$J$47 -> 250 | J29: ='CONTABILIDAD & COSTOS'!$J$47 -> 250 | K29: ='CONTABILIDAD & COSTOS'!$J$47 -> 250 | L29: ='CONTABILIDAD & COSTOS'!$J$47 -> 250 | M29: ='CONTABILIDAD & COSTOS'!$J$47 -> 250 | N29: ='CONTABILIDAD & COSTOS'!$J$47 -> 250 | ... R29: ='CONTABILIDAD & COSTOS'!$J$47 -> 250 | S29: =SUM(G29:R29) -> 3000
B30: 100 | C30: PROCESO CONVERSION 1 | D30: GASTOS FIJOS | E30: 1003103 | F30: Seguros | G30: ='CONTABILIDAD & COSTOS'!$J$59 -> 175 | H30: ='CONTABILIDAD & COSTOS'!$J$59 -> 175 | I30: ='CONTABILIDAD & COSTOS'!$J$59 -> 175 | J30: ='CONTABILIDAD & COSTOS'!$J$59 -> 175 | K30: ='CONTABILIDAD & COSTOS'!$J$59 -> 175 | L30: ='CONTABILIDAD & COSTOS'!$J$59 -> 175 | M30: ='CONTABILIDAD & COSTOS'!$J$59 -> 175 | N30: ='CONTABILIDAD & COSTOS'!$J$59 -> 175 | ... R30: ='CONTABILIDAD & COSTOS'!$J$59 -> 175 | S30: =SUM(G30:R30) -> 2100
B31: 100 | C31: PROCESO CONVERSION 1 | D31: GASTOS FIJOS | E31: 1003104 | F31: Rentas | G31: ='CONTABILIDAD & COSTOS'!$J$71 -> 1200 | H31: ='CONTABILIDAD & COSTOS'!$J$71 -> 1200 | I31: ='CONTABILIDAD & COSTOS'!$J$71 -> 1200 | J31: ='CONTABILIDAD & COSTOS'!$J$71 -> 1200 | K31: ='CONTABILIDAD & COSTOS'!$J$71 -> 1200 | L31: ='CONTABILIDAD & COSTOS'!$J$71 -> 1200 | M31: ='CONTABILIDAD & COSTOS'!$J$71 -> 1200 | N31: ='CONTABILIDAD & COSTOS'!$J$71 -> 1200 | ... R31: ='CONTABILIDAD & COSTOS'!$J$71 -> 1200 | S31: =SUM(G31:R31) -> 14400
C32: TOTALES | G32: =SUM(G4:G31) -> 206194.56 | H32: =SUM(H4:H31) -> 196137.44 | I32: =SUM(I4:I31) -> 206194.56 | J32: =SUM(J4:J31) -> 202840.39 | K32: =SUM(K4:K31) -> 206194.56 | L32: =SUM(L4:L31) -> 202840.39 | M32: =SUM(M4:M31) -> 206194.56 | N32: =SUM(N4:N31) -> 206194.56 | ... S32: =SUM(S4:S31) -> 2450860.9
B34: 110 | C34: PROCESO CONVERSION 2 | D34: MANO DE OBRA DIRECTA | E34: 1001001 | F34: Salarios | G34: =SUM('REC HUMANOS'!F13:F18)*G2 -> 58590 | H34: =$G$34/$G$2*H2 -> 52920 | I34: =$G$34/$G$2*I2 -> 58590 | J34: =$G$34/$G$2*J2 -> 56700 | K34: =$G$34/$G$2*K2 -> 58590 | L34: =$G$34/$G$2*L2 -> 56700 | M34: =$G$34/$G$2*M2 -> 58590 | N34: =$G$34/$G$2*N2 -> 58590 | O34: =$G$34/$G$2*O2 -> 56700 | ... R34: =$G$34/$G$2*R2 -> 58590 | S34: =SUM(G34:R34) -> 689850
B35: 110 | C35: PROCESO CONVERSION 2 | D35: MANO DE OBRA DIRECTA | E35: 1001002 | F35: Tiempo extra | S35: =SUM(G35:R35) -> 0
B36: 110 | C36: PROCESO CONVERSION 2 | D36: MANO DE OBRA DIRECTA | E36: 1001003 | F36: Vacaciones | S36: =SUM(G36:R36) -> 0
B37: 110 | C37: PROCESO CONVERSION 2 | D37: MANO DE OBRA DIRECTA | E37: 1001004 | F37: Prima vacacional | G37: =(((G34/G2)*15)/12)*'REC HUMANOS'!$K$6 -> 590.625 | H37: =(((H34/H2)*15)/12)*'REC HUMANOS'!$K$6 -> 590.625 | I37: =(((I34/I2)*15)/12)*'REC HUMANOS'!$K$6 -> 590.625 | J37: =(((J34/J2)*15)/12)*'REC HUMANOS'!$K$6 -> 590.625 | K37: =(((K34/K2)*15)/12)*'REC HUMANOS'!$K$6 -> 590.625 | L37: =(((L34/L2)*15)/12)*'REC HUMANOS'!$K$6 -> 590.625 | M37: =(((M34/M2)*15)/12)*'REC HUMANOS'!$K$6 -> 590.625 | N37: =(((N34/N2)*15)/12)*'REC HUMANOS'!$K$6 -> 590.625 | ... R37: =(((R34/R2)*15)/12)*'REC HUMANOS'!$K$6 -> 590.625 | S37: =SUM(G37:R37) -> 7087.5
B38: 110 | C38: PROCESO CONVERSION 2 | D38: MANO DE OBRA DIRECTA | E38: 1001005 | F38: Aguinaldo | G38: =(((G34/G2)*'REC HUMANOS'!$K$4)/12) -> 2362.5 | H38: =(((H34/H2)*'REC HUMANOS'!$K$4)/12) -> 2362.5 | I38: =(((I34/I2)*'REC HUMANOS'!$K$4)/12) -> 2362.5 | J38: =(((J34/J2)*'REC HUMANOS'!$K$4)/12) -> 2362.5 | K38: =(((K34/K2)*'REC HUMANOS'!$K$4)/12) -> 2362.5 | L38: =(((L34/L2)*'REC HUMANOS'!$K$4)/12) -> 2362.5 | M38: =(((M34/M2)*'REC HUMANOS'!$K$4)/12) -> 2362.5 | N38: =(((N34/N2)*'REC HUMANOS'!$K$4)/12) -> 2362.5 | ... R38: =(((R34/R2)*'REC HUMANOS'!$K$4)/12) -> 2362.5 | S38: =SUM(G38:R38) -> 28350
B39: 110 | C39: PROCESO CONVERSION 2 | D39: MANO DE OBRA DIRECTA | E39: 1001006 | F39: Imss | G39: =(G34*'REC HUMANOS'!$G$2)*'REC HUMANOS'!$K$9 -> 12295.697 | H39: =(H34*'REC HUMANOS'!$G$2)*'REC HUMANOS'!$K$9 -> 11105.791 | I39: =(I34*'REC HUMANOS'!$G$2)*'REC HUMANOS'!$K$9 -> 12295.697 | J39: =(J34*'REC HUMANOS'!$G$2)*'REC HUMANOS'!$K$9 -> 11899.062 | K39: =(K34*'REC HUMANOS'!$G$2)*'REC HUMANOS'!$K$9 -> 12295.697 | L39: =(L34*'REC HUMANOS'!$G$2)*'REC HUMANOS'!$K$9 -> 11899.062 | M39: =(M34*'REC HUMANOS'!$G$2)*'REC HUMANOS'!$K$9 -> 12295.697 | N39: =(N34*'REC HUMANOS'!$G$2)*'REC HUMANOS'!$K$9 -> 12295.697 | ... R39: =(R34*'REC HUMANOS'!$G$2)*'REC HUMANOS'!$K$9 -> 12295.697 | S39: =SUM(G39:R39) -> 144771.92
B40: 110 | C40: PROCESO CONVERSION 2 | D40: MANO DE OBRA DIRECTA | E40: 1001007 | F40: SAR | G40: =(G34*'REC HUMANOS'!$G$2)*'REC HUMANOS'!$K$10 -> 2766.5319 | H40: =(H34*'REC HUMANOS'!$G$2)*'REC HUMANOS'!$K$10 -> 2498.803 | I40: =(I34*'REC HUMANOS'!$G$2)*'REC HUMANOS'!$K$10 -> 2766.5319 | J40: =(J34*'REC HUMANOS'!$G$2)*'REC HUMANOS'!$K$10 -> 2677.2889 | K40: =(K34*'REC HUMANOS'!$G$2)*'REC HUMANOS'!$K$10 -> 2766.5319 | L40: =(L34*'REC HUMANOS'!$G$2)*'REC HUMANOS'!$K$10 -> 2677.2889 | M40: =(M34*'REC HUMANOS'!$G$2)*'REC HUMANOS'!$K$10 -> 2766.5319 | N40: =(N34*'REC HUMANOS'!$G$2)*'REC HUMANOS'!$K$10 -> 2766.5319 | ... R40: =(R34*'REC HUMANOS'!$G$2)*'REC HUMANOS'!$K$10 -> 2766.5319 | S40: =SUM(G40:R40) -> 32573.682
B41: 110 | C41: PROCESO CONVERSION 2 | D41: MANO DE OBRA DIRECTA | E41: 1001008 | F41: Infonavit | G41: =(G34*'REC HUMANOS'!$G$2)*'REC HUMANOS'!$K$11 -> 3073.9243 | H41: =(H34*'REC HUMANOS'!$G$2)*'REC HUMANOS'!$K$11 -> 2776.4478 | I41: =(I34*'REC HUMANOS'!$G$2)*'REC HUMANOS'!$K$11 -> 3073.9243 | J41: =(J34*'REC HUMANOS'!$G$2)*'REC HUMANOS'!$K$11 -> 2974.7655 | K41: =(K34*'REC HUMANOS'!$G$2)*'REC HUMANOS'!$K$11 -> 3073.9243 | L41: =(L34*'REC HUMANOS'!$G$2)*'REC HUMANOS'!$K$11 -> 2974.7655 | M41: =(M34*'REC HUMANOS'!$G$2)*'REC HUMANOS'!$K$11 -> 3073.9243 | N41: =(N34*'REC HUMANOS'!$G$2)*'REC HUMANOS'!$K$11 -> 3073.9243 | ... R41: =(R34*'REC HUMANOS'!$G$2)*'REC HUMANOS'!$K$11 -> 3073.9243 | S41: =SUM(G41:R41) -> 36192.98
B42: 110 | C42: PROCESO CONVERSION 2 | D42: MANO DE OBRA DIRECTA | E42: 1001009 | F42: Impuesto Estatal | G42: =(G34*'REC HUMANOS'!$G$2)*'REC HUMANOS'!$K$14 -> 1844.3546 | H42: =(H34*'REC HUMANOS'!$G$2)*'REC HUMANOS'!$K$14 -> 1665.8687 | I42: =(I34*'REC HUMANOS'!$G$2)*'REC HUMANOS'!$K$14 -> 1844.3546 | J42: =(J34*'REC HUMANOS'!$G$2)*'REC HUMANOS'!$K$14 -> 1784.8593 | K42: =(K34*'REC HUMANOS'!$G$2)*'REC HUMANOS'!$K$14 -> 1844.3546 | L42: =(L34*'REC HUMANOS'!$G$2)*'REC HUMANOS'!$K$14 -> 1784.8593 | M42: =(M34*'REC HUMANOS'!$G$2)*'REC HUMANOS'!$K$14 -> 1844.3546 | N42: =(N34*'REC HUMANOS'!$G$2)*'REC HUMANOS'!$K$14 -> 1844.3546 | ... R42: =(R34*'REC HUMANOS'!$G$2)*'REC HUMANOS'!$K$14 -> 1844.3546 | S42: =SUM(G42:R42) -> 21715.788
...

Sheet CUOTA x MIN (Calculo)
B2: ='CONTABILIDAD & COSTOS'!D4 -> PROCESO CONVERSION 1 | C2: MANO DE OBRA | D2: GASTOS VAR | E2: GASTOS FIJOS | F2: TOTAL
B3: GASTO | C3: =SUM('COSTOS (Calculo)'!S234:S242) -> 1280722.5 | D3: =SUM('COSTOS (Calculo)'!S243:S248) -> 723600 | E3: =SUM('COSTOS (Calculo)'!S249:S261) -> 976479.17 | F3: =SUM(C3:E3) -> 2980801.7
B4: MINUTOS PRODUCCION | C4: =INGENIERIA!R74+INGENIERIA!R89+INGENIERIA!R104 -> 4383446.2 | D4: =C4 -> 4383446.2 | E4: =D4 -> 4383446.2 | F4: =E4 -> 4383446.2
B5: COSTO POR MINUTO | C5: =IFERROR(C3/C4,0) -> 0.29217252 | D5: =IFERROR(D3/D4,0) -> 0.1650756 | E5: =IFERROR(E3/E4,0) -> 0.22276518 | F5: =IFERROR(F3/F4,0) -> 0.6800133
B7: ='CONTABILIDAD & COSTOS'!D5 -> PROCESO CONVERSION 2 | C7: MANO DE OBRA | D7: GASTOS VAR | E7: GASTOS FIJOS | F7: TOTAL
B8: GASTO | C8: =SUM('COSTOS (Calculo)'!S264:S272) -> 960541.87 | D8: =SUM('COSTOS (Calculo)'!S273:S278) -> 191400 | E8: =SUM('COSTOS (Calculo)'!S279:S291) -> 713308.81 | F8: =SUM(C8:E8) -> 1865250.7
B9: MINUTOS PRODUCCION | C9: =INGENIERIA!R75+INGENIERIA!R90+INGENIERIA!R105 -> 6136824.6 | D9: =C9 -> 6136824.6 | E9: =D9 -> 6136824.6 | F9: =E9 -> 6136824.6
B10: COSTO POR MINUTO | C10: =IFERROR(C8/C9,0) -> 0.15652099 | D10: =IFERROR(D8/D9,0) -> 0.031188768 | E10: =IFERROR(E8/E9,0) -> 0.11623418 | F10: =IFERROR(F8/F9,0) -> 0.30394394
B12: ='CONTABILIDAD & COSTOS'!D6 -> PROCESO CONVERSION 3 | C12: MANO DE OBRA | D12: GASTOS VAR | E12: GASTOS FIJOS | F12: TOTAL
B13: GASTO | C13: =SUM('COSTOS (Calculo)'!S294:S302) -> 960541.87 | D13: =SUM('COSTOS (Calculo)'!S303:S308) -> 167400 | E13: =SUM('COSTOS (Calculo)'!S309:S321) -> 713308.81 | F13: =SUM(C13:E13) -> 1841250.7
B14: MINUTOS PRODUCCION | C14: =INGENIERIA!R76+INGENIERIA!R91+INGENIERIA!R106 -> 3506756.9 | D14: =C14 -> 3506756.9 | E14: =D14 -> 3506756.9 | F14: =E14 -> 3506756.9
B15: COSTO POR MINUTO | C15: =IFERROR(C13/C14,0) -> 0.27391173 | D15: =IFERROR(D13/D14,0) -> 0.047736414 | E15: =IFERROR(E13/E14,0) -> 0.20340982 | F15: =IFERROR(F13/F14,0) -> 0.52505797
B17: ='CONTABILIDAD & COSTOS'!D11 -> GERENCIA GENERAL | C17: MANO DE OBRA | D17: GASTOS VAR | E17: GASTOS FIJOS | F17: TOTAL
B18: GASTO | C18: =C3+C8+C13 -> 3201806.2 | D18: =D3+D8+D13 -> 1082400 | E18: =E3+E8+E13 -> 2403096.8 | F18: =F3+F8+F13 -> 6687303
B19: MINUTOS PRODUCCION | C19: =C4+C9+C14 -> 14027028 | D19: =D4+D9+D14 -> 14027028 | E19: =E4+E9+E14 -> 14027028 | F19: =F4+F9+F14 -> 14027028
B20: COSTO POR MINUTO | C20: =C5+C10+C15 -> 0.72260524 | D20: =D5+D10+D15 -> 0.24400078 | E20: =E5+E10+E15 -> 0.54240919 | F20: =F5+F10+F15 -> 1.5090152
F22: =F3+F8+F13 -> 6687303
F23: ='COSTOS (Calculo)'!S324-F22 -> 0
F24: ='VALUACION PROD (Calculo)'!AB12-F22 -> 0

Sheet HOJAS COSTEO (calculo)
B3: CODIGO PT | C3: CODIGO MP | D3: DESCRIPCION | E3: UM | F3: CONSUMO | G3: COSTO | H3: TOTAL MP | I3: MOD | J3: GTOS V | K3: GTOS F | L3: TOTAL
B4: 9001 | C4: PRODUCTO A
C5: 1001 | D5: MATERIA PRIMA A | E5: KGS | F5: 1 | G5: =VLOOKUP(C5,COMPRAS!B:F,4,0) -> 100 | H5: =F5*G5 -> 100 | L5: =SUM(H5:K5) -> 100
C6: 1002 | D6: MATERIA PRIMA B | E6: KGS | F6: 0.5 | G6: =VLOOKUP(C6,COMPRAS!B:F,4,0) -> 55 | H6: =F6*G6 -> 27.5 | L6: =SUM(H6:K6) -> 27.5
C7: 1003 | D7: MATERIA PRIMA C | E7: KGS | F7: 0.32 | G7: =VLOOKUP(C7,COMPRAS!B:F,4,0) -> 20 | H7: =F7*G7 -> 6.4 | L7: =SUM(H7:K7) -> 6.4
C8: 1004 | D8: MATERIA PRIMA D | E8: KGS | F8: 2 | G8: =VLOOKUP(C8,COMPRAS!B:F,4,0) -> 34 | H8: =F8*G8 -> 68 | L8: =SUM(H8:K8) -> 68
C9: 1005 | D9: MATERIA PRIMA E | E9: KGS | F9: 0.67 | G9: =VLOOKUP(C9,COMPRAS!B:F,4,0) -> 15 | H9: =F9*G9 -> 10.05 | L9: =SUM(H9:K9) -> 10.05
C10: 1006 | D10: MATERIA PRIMA F | E10: KGS | F10: 0.2 | G10: =VLOOKUP(C10,COMPRAS!B:F,4,0) -> 67 | H10: =F10*G10 -> 13.4 | L10: =SUM(H10:K10) -> 13.4
C11: 1007 | D11: MATERIA PRIMA G | E11: KGS | F11: 0.1 | G11: =VLOOKUP(C11,COMPRAS!B:F,4,0) -> 22 | H11: =F11*G11 -> 2.2 | L11: =SUM(H11:K11) -> 2.2
C12: 1008 | D12: MATERIA PRIMA H | E12: KGS | F12: 0.8 | G12: =VLOOKUP(C12,COMPRAS!B:F,4,0) -> 35 | H12: =F12*G12 -> 28 | L12: =SUM(H12:K12) -> 28
C13: 1009 | D13: MATERIA PRIMA I | E13: PZA | F13: 1 | G13: =VLOOKUP(C13,COMPRAS!B:F,4,0) -> 15 | H13: =F13*G13 -> 15 | L13: =SUM(H13:K13) -> 15
C14: 1010 | D14: MATERIA PRIMA J | E14: PZA | F14: 1 | G14: =VLOOKUP(C14,COMPRAS!B:F,4,0) -> 10 | H14: =F14*G14 -> 10 | L14: =SUM(H14:K14) -> 10
C15: WC1 1P | D15: TIEMPO DE PROCESO 1 | E15: MIN | F15: =INGENIERIA!F14 -> 5 | I15: =$F$15*'CUOTA x MIN (Calculo)'!C5 -> 1.4608626 | J15: =$F$15*'CUOTA x MIN (Calculo)'!D5 -> 0.825378 | K15: =$F$15*'CUOTA x MIN (Calculo)'!E5 -> 1.1138259 | L15: =SUM(H15:K15) -> 3.4000665
C16: WC1 2P | D16: TIEMPO DE PROCESO 2 | E16: MIN | F16: =INGENIERIA!F15 -> 7 | I16: =$F$16*'CUOTA x MIN (Calculo)'!C10 -> 1.0956469 | J16: =$F$16*'CUOTA x MIN (Calculo)'!D10 -> 0.21832138 | K16: =$F$16*'CUOTA x MIN (Calculo)'!E10 -> 0.81363929 | L16: =SUM(H16:K16) -> 2.1276076
C17: WC1 3P | D17: TIEMPO DE PROCESO 3 | E17: MIN | F17: =INGENIERIA!F16 -> 4 | I17: =$F$17*'CUOTA x MIN (Calculo)'!C15 -> 1.0956469 | J17: =$F$17*'CUOTA x MIN (Calculo)'!D15 -> 0.19094566 | K17: =$F$17*'CUOTA x MIN (Calculo)'!E15 -> 0.81363929 | L17: =SUM(H17:K17) -> 2.1002319
D18: COSTO TOTAL | H18: =SUM(H5:H17) -> 280.55 | I18: =SUM(I5:I17) -> 3.6521565 | J18: =SUM(J5:J17) -> 1.234645 | K18: =SUM(K5:K17) -> 2.7411045 | L18: =SUM(L5:L17) -> 288.17791
B21: CODIGO PT | C21: CODIGO MP | D21: DESCRIPCION | E21: UM | F21: CONSUMO | G21: COSTO | H21: TOTAL MP | I21: MOD | J21: GTOS V | K21: GTOS F | L21: TOTAL
B22: 9002 | C22: PRODUCTO B
C23: 1001 | D23: MATERIA PRIMA A | E23: KGS | F23: =INGENIERIA!F19 -> 0.84 | G23: =VLOOKUP(C23,COMPRAS!B:F,4,0) -> 100 | H23: =F23*G23 -> 84 | L23: =SUM(H23:K23) -> 84
C24: 1002 | D24: MATERIA PRIMA B | E24: KGS | F24: =INGENIERIA!F20 -> 0.42 | G24: =VLOOKUP(C24,COMPRAS!B:F,4,0) -> 55 | H24: =F24*G24 -> 23.1 | L24: =SUM(H24:K24) -> 23.1
C25: 1003 | D25: MATERIA PRIMA C | E25: KGS | F25: =INGENIERIA!F21 -> 0.2688 | G25: =VLOOKUP(C25,COMPRAS!B:F,4,0) -> 20 | H25: =F25*G25 -> 5.376 | L25: =SUM(H25:K25) -> 5.376
C26: 1004 | D26: MATERIA PRIMA D | E26: KGS | F26: =INGENIERIA!F22 -> 1.68 | G26: =VLOOKUP(C26,COMPRAS!B:F,4,0) -> 34 | H26: =F26*G26 -> 57.12 | L26: =SUM(H26:K26) -> 57.12
C27: 1005 | D27: MATERIA PRIMA E | E27: KGS | F27: =INGENIERIA!F23 -> 0.5628 | G27: =VLOOKUP(C27,COMPRAS!B:F,4,0) -> 15 | H27: =F27*G27 -> 8.442 | L27: =SUM(H27:K27) -> 8.442
C28: 1006 | D28: MATERIA PRIMA F | E28: KGS | F28: =INGENIERIA!F24 -> 0.168 | G28: =VLOOKUP(C28,COMPRAS!B:F,4,0) -> 67 | H28: =F28*G28 -> 11.256 | L28: =SUM(H28:K28) -> 11.256
C29: 1007 | D29: MATERIA PRIMA G | E29: KGS | F29: =INGENIERIA!F25 -> 0.084 | G29: =VLOOKUP(C29,COMPRAS!B:F,4,0) -> 22 | H29: =F29*G29 -> 1.848 | L29: =SUM(H29:K29) -> 1.848
C30: 1008 | D30: MATERIA PRIMA H | E30: KGS | F30: =INGENIERIA!F26 -> 0.672 | G30: =VLOOKUP(C30,COMPRAS!B:F,4,0) -> 35 | H30: =F30*G30 -> 23.52 | L30: =SUM(H30:K30) -> 23.52
C31: 1009 | D31: MATERIA PRIMA I | E31: PZA | F31: =INGENIERIA!F27 -> 1 | G31: =VLOOKUP(C31,COMPRAS!B:F,4,0) -> 15 | H31: =F31*G31 -> 15 | L31: =SUM(H31:K31) -> 15
C32: 1010 | D32: MATERIA PRIMA J | E32: PZA | F32: =INGENIERIA!F28 -> 1 | G32: =VLOOKUP(C32,COMPRAS!B:F,4,0) -> 10 | H32: =F32*G32 -> 10 | L32: =SUM(H32:K32) -> 10
C33: WC1 1P | D33: TIEMPO DE PROCESO 1 | E33: MIN | F33: =INGENIERIA!F29 -> 5.5 | I33: =$F$33*'CUOTA x MIN (Calculo)'!C5 -> 1.6069488 | J33: =$F$33*'CUOTA x MIN (Calculo)'!D5 -> 0.9079158 | K33: =$F$33*'CUOTA x MIN (Calculo)'!E5 -> 1.2252085 | L33: =SUM(H33:K33) -> 3.7400731
C34: WC1 2P | D34: TIEMPO DE PROCESO 2 | E34: MIN | F34: =INGENIERIA!F30 -> 7.7 | I34: =$F$34*'CUOTA x MIN (Calculo)'!C10 -> 1.2052116 | J34: =$F$34*'CUOTA x MIN (Calculo)'!D10 -> 0.24015351 | K34: =$F$34*'CUOTA x MIN (Calculo)'!E10 -> 0.89500322 | L34: =SUM(H34:K34) -> 2.3403684
C35: WC1 3P | D35: TIEMPO DE PROCESO 3 | E35: MIN | F35: =INGENIERIA!F31 -> 4.4 | I35: =$F$35*'CUOTA x MIN (Calculo)'!C15 -> 1.2052116 | J35: =$F$35*'CUOTA x MIN (Calculo)'!D15 -> 0.21004022 | K35: =$F$35*'CUOTA x MIN (Calculo)'!E15 -> 0.89500322 | L35: =SUM(H35:K35) -> 2.3102551
D36: COSTO TOTAL | H36: =SUM(H23:H35) -> 239.662 | I36: =SUM(I23:I35) -> 4.0173721 | J36: =SUM(J23:J35) -> 1.3581095 | K36: =SUM(K23:K35) -> 3.0152149 | L36: =SUM(L23:L35) -> 248.0527
B39: CODIGO PT | C39: CODIGO MP | D39: DESCRIPCION | E39: UM | F39: CONSUMO | G39: COSTO | H39: TOTAL MP | I39: MOD | J39: GTOS V | K39: GTOS F | L39: TOTAL
B40: 9003 | C40: PRODUCTO C
C41: 1001 | D41: MATERIA PRIMA A | E41: KGS | F41: =INGENIERIA!F34 -> 1.05 | G41: =VLOOKUP(C41,COMPRAS!B:F,4,0) -> 100 | H41: =F41*G41 -> 105 | L41: =SUM(H41:K41) -> 105
C42: 1002 | D42: MATERIA PRIMA B | E42: KGS | F42: =INGENIERIA!F35 -> 0.525 | G42: =VLOOKUP(C42,COMPRAS!B:F,4,0) -> 55 | H42: =F42*G42 -> 28.875 | L42: =SUM(H42:K42) -> 28.875
C43: 1003 | D43: MATERIA PRIMA C | E43: KGS | F43: =INGENIERIA!F36 -> 0.336 | G43: =VLOOKUP(C43,COMPRAS!B:F,4,0) -> 20 | H43: =F43*G43 -> 6.72 | L43: =SUM(H43:K43) -> 6.72
C44: 1004 | D44: MATERIA PRIMA D | E44: KGS | F44: =INGENIERIA!F37 -> 2.1 | G44: =VLOOKUP(C44,COMPRAS!B:F,4,0) -> 34 | H44: =F44*G44 -> 71.4 | L44: =SUM(H44:K44) -> 71.4
C45: 1005 | D45: MATERIA PRIMA E | E45: KGS | F45: =INGENIERIA!F38 -> 0.7035 | G45: =VLOOKUP(C45,COMPRAS!B:F,4,0) -> 15 | H45: =F45*G45 -> 10.5525 | L45: =SUM(H45:K45) -> 10.5525
C46: 1006 | D46: MATERIA PRIMA F | E46: KGS | F46: =INGENIERIA!F39 -> 0.21 | G46: =VLOOKUP(C46,COMPRAS!B:F,4,0) -> 67 | H46: =F46*G46 -> 14.07 | L46: =SUM(H46:K46) -> 14.07
...

Sheet VALUACION PROD (Calculo)
B5: VALUACION DE LA PRODUCCION
B6: COD | C6: PRODUCTO | E6: ENERO | F6: FEBRERO | G6: MARZO | H6: ABRIL | I6: MAYO | J6: JUNIO | K6: JULIO | L6: AGOSTO | M6: SEPTIEMBRE | N6: OCTUBRE | O6: NOVIEMBRE | P6: DICIEMBRE | Q6: TOTAL | S6: TOTAL MP | T6: MOD | U6: GTOS V | V6: GTOS F | W6: TOTAL | Y6: TOTAL MP | Z6: MOD | AA6: GTOS V | AB6: GTOS F | AC6: TOTAL
B7: 9001 | C7: PRODUCTO A | E7: =INGENIERIA!F56 -> 25000 | F7: =INGENIERIA!G56 -> 23076.923 | G7: =INGENIERIA!H56 -> 25000 | H7: =INGENIERIA!I56 -> 23076.923 | I7: =INGENIERIA!J56 -> 24000 | J7: =INGENIERIA!K56 -> 23076.923 | K7: =INGENIERIA!L56 -> 25000 | L7: =INGENIERIA!M56 -> 23076.923 | ... P7: =INGENIERIA!Q56 -> 25000 | Q7: =SUM(E7:P7) -> 288384.62 | S7: ='HOJAS COSTEO (calculo)'!H18 -> 280.55 | T7: ='HOJAS COSTEO (calculo)'!I18 -> 3.6521565 | U7: ='HOJAS COSTEO (calculo)'!J18 -> 1.234645 | V7: ='HOJAS COSTEO (calculo)'!K18 -> 2.7411045 | W7: ='HOJAS COSTEO (calculo)'!L18 -> 288.17791 | Y7: =$Q$7*S7 -> 80906304 | Z7: =$Q$7*T7 -> 1053225.7 | AA7: =$Q$7*U7 -> 356052.63 | AB7: =$Q$7*V7 -> 790492.36 | AC7: =$Q$7*W7 -> 83106075
B8: 9002 | C8: PRODUCTO B | E8: =INGENIERIA!F57 -> 30000 | F8: =INGENIERIA!G57 -> 27692.308 | G8: =INGENIERIA!H57 -> 30000 | H8: =INGENIERIA!I57 -> 27692.308 | I8: =INGENIERIA!J57 -> 28800 | J8: =INGENIERIA!K57 -> 27692.308 | K8: =INGENIERIA!L57 -> 30000 | L8: =INGENIERIA!M57 -> 27692.308 | ... P8: =INGENIERIA!Q57 -> 30000 | Q8: =SUM(E8:P8) -> 346061.54 | S8: ='HOJAS COSTEO (calculo)'!H36 -> 239.662 | T8: ='HOJAS COSTEO (calculo)'!I36 -> 4.0173721 | U8: ='HOJAS COSTEO (calculo)'!J36 -> 1.3581095 | V8: ='HOJAS COSTEO (calculo)'!K36 -> 3.0152149 | W8: ='HOJAS COSTEO (calculo)'!L36 -> 248.0527 | Y8: =$Q$8*S8 -> 82937800 | Z8: =$Q$8*T8 -> 1390258 | AA8: =$Q$8*U8 -> 469989.47 | AB8: =$Q$8*V8 -> 1043449.9 | AC8: =$Q$8*W8 -> 85841498
B9: 9003 | C9: PRODUCTO C | E9: =INGENIERIA!F58 -> 20000 | F9: =INGENIERIA!G58 -> 18461.538 | G9: =INGENIERIA!H58 -> 20000 | H9: =INGENIERIA!I58 -> 18461.538 | I9: =INGENIERIA!J58 -> 19200 | J9: =INGENIERIA!K58 -> 18461.538 | K9: =INGENIERIA!L58 -> 20000 | L9: =INGENIERIA!M58 -> 18461.538 | ... P9: =INGENIERIA!Q58 -> 20000 | Q9: =SUM(E9:P9) -> 230707.69 | S9: ='HOJAS COSTEO (calculo)'!H54 -> 293.3275 | T9: ='HOJAS COSTEO (calculo)'!I54 -> 3.2869408 | U9: ='HOJAS COSTEO (calculo)'!J54 -> 1.1111805 | V9: ='HOJAS COSTEO (calculo)'!K54 -> 2.466994 | W9: ='HOJAS COSTEO (calculo)'!L54 -> 300.19262 | Y9: =$Q$9*S9 -> 67672911 | Z9: =$Q$9*T9 -> 758322.53 | AA9: =$Q$9*U9 -> 256357.89 | AB9: =$Q$9*V9 -> 569154.5 | AC9: =$Q$9*W9 -> 69256746
E10: =SUM(E7:E9) -> 75000 | F10: =SUM(F7:F9) -> 69230.769 | G10: =SUM(G7:G9) -> 75000 | H10: =SUM(H7:H9) -> 69230.769 | I10: =SUM(I7:I9) -> 72000 | J10: =SUM(J7:J9) -> 69230.769 | K10: =SUM(K7:K9) -> 75000 | L10: =SUM(L7:L9) -> 69230.769 | ... Q10: =SUM(Q7:Q9) -> 865153.85 | Y10: =SUM(Y7:Y9) -> 2.3151701e+08 | Z10: =SUM(Z7:Z9) -> 3201806.2 | AA10: =SUM(AA7:AA9) -> 1082400 | AB10: =SUM(AB7:AB9) -> 2403096.8 | AC10: =SUM(AC7:AC9) -> 2.3820432e+08
Y11: =INGENIERIA!U107-Y10 -> 0
C12: TOTAL MP | E12: =SUMPRODUCT(E7:E9,$S$7:$S$9) -> 20070160 | F12: =SUMPRODUCT(F7:F9,$S$7:$S$9) -> 18526302 | G12: =SUMPRODUCT(G7:G9,$S$7:$S$9) -> 20070160 | H12: =SUMPRODUCT(H7:H9,$S$7:$S$9) -> 18526302 | I12: =SUMPRODUCT(I7:I9,$S$7:$S$9) -> 19267354 | J12: =SUMPRODUCT(J7:J9,$S$7:$S$9) -> 18526302 | K12: =SUMPRODUCT(K7:K9,$S$7:$S$9) -> 20070160 | L12: =SUMPRODUCT(L7:L9,$S$7:$S$9) -> 18526302 | ... P12: =SUMPRODUCT(P7:P9,$S$7:$S$9) -> 20070160 | Q12: =SUM(E12:P12) -> 2.3151701e+08 | AB12: =SUM(Z10:AB10) -> 6687303
C13: MOD | E13: =SUMPRODUCT(E7:E9,$T$7:$T$9) -> 277563.89 | F13: =SUMPRODUCT(F7:F9,$T$7:$T$9) -> 256212.82 | G13: =SUMPRODUCT(G7:G9,$T$7:$T$9) -> 277563.89 | H13: =SUMPRODUCT(H7:H9,$T$7:$T$9) -> 256212.82 | I13: =SUMPRODUCT(I7:I9,$T$7:$T$9) -> 266461.34 | J13: =SUMPRODUCT(J7:J9,$T$7:$T$9) -> 256212.82 | K13: =SUMPRODUCT(K7:K9,$T$7:$T$9) -> 277563.89 | L13: =SUMPRODUCT(L7:L9,$T$7:$T$9) -> 256212.82 | ... P13: =SUMPRODUCT(P7:P9,$T$7:$T$9) -> 277563.89 | Q13: =SUM(E13:P13) -> 3201806.2
C14: GTOS V | E14: =SUMPRODUCT(E7:E9,$U$7:$U$9) -> 93833.022 | F14: =SUMPRODUCT(F7:F9,$U$7:$U$9) -> 86615.097 | G14: =SUMPRODUCT(G7:G9,$U$7:$U$9) -> 93833.022 | H14: =SUMPRODUCT(H7:H9,$U$7:$U$9) -> 86615.097 | I14: =SUMPRODUCT(I7:I9,$U$7:$U$9) -> 90079.701 | J14: =SUMPRODUCT(J7:J9,$U$7:$U$9) -> 86615.097 | K14: =SUMPRODUCT(K7:K9,$U$7:$U$9) -> 93833.022 | L14: =SUMPRODUCT(L7:L9,$U$7:$U$9) -> 86615.097 | ... P14: =SUMPRODUCT(P7:P9,$U$7:$U$9) -> 93833.022 | Q14: =SUM(E14:P14) -> 1082400
C15: GTOS F | E15: =SUMPRODUCT(E7:E9,$V$7:$V$9) -> 208323.94 | F15: =SUMPRODUCT(F7:F9,$V$7:$V$9) -> 192299.02 | G15: =SUMPRODUCT(G7:G9,$V$7:$V$9) -> 208323.94 | H15: =SUMPRODUCT(H7:H9,$V$7:$V$9) -> 192299.02 | I15: =SUMPRODUCT(I7:I9,$V$7:$V$9) -> 199990.98 | J15: =SUMPRODUCT(J7:J9,$V$7:$V$9) -> 192299.02 | K15: =SUMPRODUCT(K7:K9,$V$7:$V$9) -> 208323.94 | L15: =SUMPRODUCT(L7:L9,$V$7:$V$9) -> 192299.02 | ... P15: =SUMPRODUCT(P7:P9,$V$7:$V$9) -> 208323.94 | Q15: =SUM(E15:P15) -> 2403096.8
C16: TOTAL | E16: =SUM(E12:E15) -> 20649881 | F16: =SUM(F12:F15) -> 19061428 | G16: =SUM(G12:G15) -> 20649881 | H16: =SUM(H12:H15) -> 19061428 | I16: =SUM(I12:I15) -> 19823886 | J16: =SUM(J12:J15) -> 19061428 | K16: =SUM(K12:K15) -> 20649881 | L16: =SUM(L12:L15) -> 19061428 | ... Q16: =SUM(Q12:Q15) -> 2.3820432e+08

Sheet VENTAS
B2: CALCULO PRECIO | D2: COSTOS INDUSTRIALES | I2: 0.12 | K2: 0.2
B3: COD | C3: PRODUCTO | D3: TOTAL MP | E3: MOD | F3: GTOS V | G3: GTOS F | H3: TOTAL | I3: GTOS OPERATIVO | J3: TOTAL COSTO | K3: MARGEN | L3: PRECIO VTA
B4: 9001 | C4: PRODUCTO A | D4: ='HOJAS COSTEO (calculo)'!H18 -> 280.55 | E4: ='HOJAS COSTEO (calculo)'!I18 -> 3.6521565 | F4: ='HOJAS COSTEO (calculo)'!J18 -> 1.234645 | G4: ='HOJAS COSTEO (calculo)'!K18 -> 2.7411045 | H4: ='HOJAS COSTEO (calculo)'!L18 -> 288.17791 | I4: =H4*I2 -> 34.581349 | J4: =H4+I4 -> 322.75925 | K4: =(J4/(1-K2))-J4 -> 80.689814 | L4: =J4/(1-$K$2) -> 403.44907
B5: 9002 | C5: PRODUCTO B | D5: ='HOJAS COSTEO (calculo)'!H36 -> 239.662 | E5: ='HOJAS COSTEO (calculo)'!I36 -> 4.0173721 | F5: ='HOJAS COSTEO (calculo)'!J36 -> 1.3581095 | G5: ='HOJAS COSTEO (calculo)'!K36 -> 3.0152149 | H5: ='HOJAS COSTEO (calculo)'!L36 -> 248.0527 | I5: =H5*I2 -> 29.766324 | J5: =H5+I5 -> 277.81902 | K5: =(J5/(1-K2))-J5 -> 69.454755 | L5: =J5/(1-$K$2) -> 347.27378
B6: 9003 | C6: PRODUCTO C | D6: ='HOJAS COSTEO (calculo)'!H54 -> 293.3275 | E6: ='HOJAS COSTEO (calculo)'!I54 -> 3.2869408 | F6: ='HOJAS COSTEO (calculo)'!J54 -> 1.1111805 | G6: ='HOJAS COSTEO (calculo)'!K54 -> 2.466994 | H6: ='HOJAS COSTEO (calculo)'!L54 -> 300.19262 | I6: =H6*I2 -> 36.023114 | J6: =H6+I6 -> 336.21573 | K6: =(J6/(1-K2))-J6 -> 84.053932 | L6: =J6/(1-$K$2) -> 420.26966
B10: VENTAS EN KGS
B11: COD | C11: PRODUCTO | D11: ENERO | E11: FEBRERO | F11: MARZO | G11: ABRIL | H11: MAYO | I11: JUNIO | J11: JULIO | K11: AGOSTO | L11: SEPTIEMBRE | M11: OCTUBRE | N11: NOVIEMBRE | O11: DICIEMBRE | P11: TOTAL | Q11: VENTA $
B12: 9001 | C12: PRODUCTO A | D12: =INGENIERIA!F56 -> 25000 | E12: =INGENIERIA!G56 -> 23076.923 | F12: =INGENIERIA!H56 -> 25000 | G12: =INGENIERIA!I56 -> 23076.923 | H12: =INGENIERIA!J56 -> 24000 | I12: =INGENIERIA!K56 -> 23076.923 | J12: =INGENIERIA!L56 -> 25000 | K12: =INGENIERIA!M56 -> 23076.923 | ... P12: =INGENIERIA!R56 -> 288384.62 | Q12: =P12*L4 -> 1.163485e+08
B13: 9002 | C13: PRODUCTO B | D13: =INGENIERIA!F57 -> 30000 | E13: =INGENIERIA!G57 -> 27692.308 | F13: =INGENIERIA!H57 -> 30000 | G13: =INGENIERIA!I57 -> 27692.308 | H13: =INGENIERIA!J57 -> 28800 | I13: =INGENIERIA!K57 -> 27692.308 | J13: =INGENIERIA!L57 -> 30000 | K13: =INGENIERIA!M57 -> 27692.308 | ... P13: =INGENIERIA!R57 -> 346061.54 | Q13: =P13*L5 -> 1.201781e+08
B14: 9003 | C14: PRODUCTO C | D14: =INGENIERIA!F58 -> 20000 | E14: =INGENIERIA!G58 -> 18461.538 | F14: =INGENIERIA!H58 -> 20000 | G14: =INGENIERIA!I58 -> 18461.538 | H14: =INGENIERIA!J58 -> 19200 | I14: =INGENIERIA!K58 -> 18461.538 | J14: =INGENIERIA!L58 -> 20000 | K14: =INGENIERIA!M58 -> 18461.538 | ... P14: =INGENIERIA!R58 -> 230707.69 | Q14: =P14*L6 -> 96959444
D15: =SUM(D12:D14) -> 75000 | E15: =SUM(E12:E14) -> 69230.769 | F15: =SUM(F12:F14) -> 75000 | G15: =SUM(G12:G14) -> 69230.769 | H15: =SUM(H12:H14) -> 72000 | I15: =SUM(I12:I14) -> 69230.769 | J15: =SUM(J12:J14) -> 75000 | K15: =SUM(K12:K14) -> 69230.769 | ... Q15: =SUM(Q12:Q14) -> 3.3348605e+08
B18: VENTAS EN PESOS
B19: COD | C19: PRODUCTO | D19: ENERO | E19: FEBRERO | F19: MARZO | G19: ABRIL | H19: MAYO | I19: JUNIO | J19: JULIO | K19: AGOSTO | L19: SEPTIEMBRE | M19: OCTUBRE | N19: NOVIEMBRE | O19: DICIEMBRE | P19: TOTAL
B20: 9001 | C20: PRODUCTO A | D20: =D12*$L$4 -> 10086227 | E20: =E12*$L$4 -> 9310363.1 | F20: =F12*$L$4 -> 10086227 | G20: =G12*$L$4 -> 9310363.1 | H20: =H12*$L$4 -> 9682777.6 | I20: =I12*$L$4 -> 9310363.1 | J20: =J12*$L$4 -> 10086227 | K20: =K12*$L$4 -> 9310363.1 | ... O20: =O12*$L$4 -> 10086227 | P20: =SUM(D20:O20) -> 1.163485e+08
B21: 9002 | C21: PRODUCTO B | D21: =D13*$L$5 -> 10418213 | E21: =E13*$L$5 -> 9616812.2 | F21: =F13*$L$5 -> 10418213 | G21: =G13*$L$5 -> 9616812.2 | H21: =H13*$L$5 -> 10001485 | I21: =I13*$L$5 -> 9616812.2 | J21: =J13*$L$5 -> 10418213 | K21: =K13*$L$5 -> 9616812.2 | ... O21: =O13*$L$5 -> 10418213 | P21: =SUM(D21:O21) -> 1.201781e+08
B22: 9003 | C22: PRODUCTO C | D22: =D14*$L$6 -> 8405393.2 | E22: =E14*$L$6 -> 7758824.5 | F22: =F14*$L$6 -> 8405393.2 | G22: =G14*$L$6 -> 7758824.5 | H22: =H14*$L$6 -> 8069177.5 | I22: =I14*$L$6 -> 7758824.5 | J22: =J14*$L$6 -> 8405393.2 | K22: =K14*$L$6 -> 7758824.5 | ... O22: =O14*$L$6 -> 8405393.2 | P22: =SUM(D22:O22) -> 96959444
D23: =SUM(D20:D22) -> 28909833 | E23: =SUM(E20:E22) -> 26686000 | F23: =SUM(F20:F22) -> 28909833 | G23: =SUM(G20:G22) -> 26686000 | H23: =SUM(H20:H22) -> 27753440 | I23: =SUM(I20:I22) -> 26686000 | J23: =SUM(J20:J22) -> 28909833 | K23: =SUM(K20:K22) -> 26686000 | ... P23: =SUM(P20:P22) -> 3.3348605e+08

Sheet P&L FCTS
C2: ENERO | D2: FEBRERO | E2: MARZO | F2: ABRIL | G2: MAYO | H2: JUNIO | I2: JULIO | J2: AGOSTO | K2: SEPTIEMBRE | L2: OCTUBRE | M2: NOVIEMBRE | N2: DICIEMBRE | O2: TOTAL
B3: VENTAS | C3: =VENTAS!D23 -> 28909833 | D3: =VENTAS!E23 -> 26686000 | E3: =VENTAS!F23 -> 28909833 | F3: =VENTAS!G23 -> 26686000 | G3: =VENTAS!H23 -> 27753440 | H3: =VENTAS!I23 -> 26686000 | I3: =VENTAS!J23 -> 28909833 | J3: =VENTAS!K23 -> 26686000 | ... O3: =VENTAS!P23 -> 3.3348605e+08
B5: COSTO DE VENTAS | C5: ='VALUACION PROD (Calculo)'!E16 -> 20649881 | D5: ='VALUACION PROD (Calculo)'!F16 -> 19061428 | E5: ='VALUACION PROD (Calculo)'!G16 -> 20649881 | F5: ='VALUACION PROD (Calculo)'!H16 -> 19061428 | G5: ='VALUACION PROD (Calculo)'!I16 -> 19823886 | H5: ='VALUACION PROD (Calculo)'!J16 -> 19061428 | I5: ='VALUACION PROD (Calculo)'!K16 -> 20649881 | J5: ='VALUACION PROD (Calculo)'!L16 -> 19061428 | ... O5: ='VALUACION PROD (Calculo)'!Q16 -> 2.3820432e+08
B6: VARIACIONES | C6: ='COSTOS (Calculo)'!G330 -> -17626.432 | D6: ='COSTOS (Calculo)'!H330 -> 2205.3923 | E6: ='COSTOS (Calculo)'!I330 -> -17626.432 | F6: ='COSTOS (Calculo)'!J330 -> 18700.49 | G6: ='COSTOS (Calculo)'!K330 -> 5562.4026 | H6: ='COSTOS (Calculo)'!L330 -> 18700.49 | I6: ='COSTOS (Calculo)'!M330 -> -17626.432 | J6: ='COSTOS (Calculo)'!N330 -> 26967.48 | ... O6: ='COSTOS (Calculo)'!S330 -> 0
B7: TOTAL COSTO | C7: =C5+C6 -> 20632254 | D7: =D5+D6 -> 19063634 | E7: =E5+E6 -> 20632254 | F7: =F5+F6 -> 19080129 | G7: =G5+G6 -> 19829448 | H7: =H5+H6 -> 19080129 | I7: =I5+I6 -> 20632254 | J7: =J5+J6 -> 19088396 | ... O7: =O5+O6 -> 2.3820432e+08
B9: UTILIDAD BRUTA | C9: =C3-C7 -> 8277578.8 | D9: =D3-D7 -> 7622366 | E9: =E3-E7 -> 8277578.8 | F9: =F3-F7 -> 7605870.9 | G9: =G3-G7 -> 7923991.8 | H9: =H3-H7 -> 7605870.9 | I9: =I3-I7 -> 8277578.8 | J9: =J3-J7 -> 7597603.9 | ... O9: =O3-O7 -> 95281727
C10: =C9/C3 -> 0.28632399 | D10: =D9/D3 -> 0.28563164 | E10: =E9/E3 -> 0.28632399 | F10: =F9/F3 -> 0.28501353 | G10: =G9/G3 -> 0.28551386 | H10: =H9/H3 -> 0.28501353 | I10: =I9/I3 -> 0.28632399 | J10: =J9/J3 -> 0.28470374 | ... O10: =O9/O3 -> 0.28571429
B12: GASTOS DE OPERACIÓN | C12: =C5*0.12 -> 2477985.7 | D12: =D5*0.12 -> 2287371.4 | E12: =E5*0.12 -> 2477985.7 | F12: =F5*0.12 -> 2287371.4 | G12: =G5*0.12 -> 2378866.3 | H12: =H5*0.12 -> 2287371.4 | I12: =I5*0.12 -> 2477985.7 | J12: =J5*0.12 -> 2287371.4 | ... O12: =O5*0.12 -> 28584518
B14: UTILIDAD OPERACIÓN | C14: =C9-C12 -> 5799593.1 | D14: =D9-D12 -> 5334994.6 | E14: =E9-E12 -> 5799593.1 | F14: =F9-F12 -> 5318499.5 | G14: =G9-G12 -> 5545125.6 | H14: =H9-H12 -> 5318499.5 | I14: =I9-I12 -> 5799593.1 | J14: =J9-J12 -> 5310232.5 | ... O14: =O9-O12 -> 66697209
C15: =C14/C3 -> 0.2006097 | D15: =D14/D3 -> 0.19991736 | E15: =E14/E3 -> 0.2006097 | F15: =F14/F3 -> 0.19929924 | G15: =G14/G3 -> 0.19979958 | H15: =H14/H3 -> 0.19929924 | I15: =I14/I3 -> 0.2006097 | J15: =J14/J3 -> 0.19898945 | ... O15: =O14/O3 -> 0.2

Sheet PROD REAL
B2: VALUACION DE LA PRODUCCION
B3: COD | C3: PRODUCTO | D3: ENERO | F3: TOTAL MP | G3: MOD | H3: GTOS V | I3: GTOS F | J3: TOTAL | L3: TOTAL MP | M3: MOD | N3: GTOS V | O3: GTOS F | P3: TOTAL
B4: 9001 | C4: PRODUCTO A | D4: 35000 | F4: ='VALUACION PROD (Calculo)'!S7 -> 280.55 | G4: ='VALUACION PROD (Calculo)'!T7 -> 3.6521565 | H4: ='VALUACION PROD (Calculo)'!U7 -> 1.234645 | I4: ='VALUACION PROD (Calculo)'!V7 -> 2.7411045 | J4: =SUM(F4:I4) -> 288.17791 | L4: =$D$4*F4 -> 9819250 | M4: =$D$4*G4 -> 127825.48 | N4: =$D$4*H4 -> 43212.576 | O4: =$D$4*I4 -> 95938.657 | P4: =$D$4*J4 -> 10086227
B5: 9002 | C5: PRODUCTO B | D5: 10000 | F5: ='VALUACION PROD (Calculo)'!S8 -> 239.662 | G5: ='VALUACION PROD (Calculo)'!T8 -> 4.0173721 | H5: ='VALUACION PROD (Calculo)'!U8 -> 1.3581095 | I5: ='VALUACION PROD (Calculo)'!V8 -> 3.0152149 | J5: =SUM(F5:I5) -> 248.0527 | L5: =$D$5*F5 -> 2396620 | M5: =$D$5*G5 -> 40173.721 | N5: =$D$5*H5 -> 13581.095 | O5: =$D$5*I5 -> 30152.149 | P5: =$D$5*J5 -> 2480527
B6: 9003 | C6: PRODUCTO C | D6: 25000 | F6: ='VALUACION PROD (Calculo)'!S9 -> 293.3275 | G6: ='VALUACION PROD (Calculo)'!T9 -> 3.2869408 | H6: ='VALUACION PROD (Calculo)'!U9 -> 1.1111805 | I6: ='VALUACION PROD (Calculo)'!V9 -> 2.466994 | J6: =SUM(F6:I6) -> 300.19262 | L6: =$D$6*F6 -> 7333187.5 | M6: =$D$6*G6 -> 82173.52 | N6: =$D$6*H6 -> 27779.513 | O6: =$D$6*I6 -> 61674.851 | P6: =$D$6*J6 -> 7504815.4
D7: =SUM(D4:D6) -> 70000 | L7: =SUM(L4:L6) -> 19549058 | M7: =SUM(M4:M6) -> 250172.72 | N7: =SUM(N4:N6) -> 84573.184 | O7: =SUM(O4:O6) -> 187765.66 | P7: =SUM(P4:P6) -> 20071569
C8: FCTS | D8: ='VALUACION PROD (Calculo)'!E10 -> 75000
B10: CONSUMO A ESTANDAR
B11: EXPLOSION DE MATERIALES
B12: 9001 | C12: PRODUCTO A
C13: 1001 | D13: MATERIA PRIMA A | E13: KGS | F13: =$D$4*INGENIERIA!F4 -> 35000 | G13: =VLOOKUP(C13,COMPRAS!B:F,4,0) -> 100 | H13: =F13*G13 -> 3500000
C14: 1002 | D14: MATERIA PRIMA B | E14: KGS | F14: =$D$4*INGENIERIA!F5 -> 17500 | G14: =VLOOKUP(C14,COMPRAS!B:F,4,0) -> 55 | H14: =F14*G14 -> 962500
C15: 1003 | D15: MATERIA PRIMA C | E15: KGS | F15: =$D$4*INGENIERIA!F6 -> 11200 | G15: =VLOOKUP(C15,COMPRAS!B:F,4,0) -> 20 | H15: =F15*G15 -> 224000
C16: 1004 | D16: MATERIA PRIMA D | E16: KGS | F16: =$D$4*INGENIERIA!F7 -> 70000 | G16: =VLOOKUP(C16,COMPRAS!B:F,4,0) -> 34 | H16: =F16*G16 -> 2380000
C17: 1005 | D17: MATERIA PRIMA E | E17: KGS | F17: =$D$4*INGENIERIA!F8 -> 23450 | G17: =VLOOKUP(C17,COMPRAS!B:F,4,0) -> 15 | H17: =F17*G17 -> 351750
C18: 1006 | D18: MATERIA PRIMA F | E18: KGS | F18: =$D$4*INGENIERIA!F9 -> 7000 | G18: =VLOOKUP(C18,COMPRAS!B:F,4,0) -> 67 | H18: =F18*G18 -> 469000
C19: 1007 | D19: MATERIA PRIMA G | E19: KGS | F19: =$D$4*INGENIERIA!F10 -> 3500 | G19: =VLOOKUP(C19,COMPRAS!B:F,4,0) -> 22 | H19: =F19*G19 -> 77000
C20: 1008 | D20: MATERIA PRIMA H | E20: KGS | F20: =$D$4*INGENIERIA!F11 -> 28000 | G20: =VLOOKUP(C20,COMPRAS!B:F,4,0) -> 35 | H20: =F20*G20 -> 980000
C21: 1009 | D21: MATERIA PRIMA I | E21: PZA | F21: =$D$4*INGENIERIA!F12 -> 35000 | G21: =VLOOKUP(C21,COMPRAS!B:F,4,0) -> 15 | H21: =F21*G21 -> 525000
C22: 1010 | D22: MATERIA PRIMA J | E22: PZA | F22: =$D$4*INGENIERIA!F13 -> 35000 | G22: =VLOOKUP(C22,COMPRAS!B:F,4,0) -> 10 | H22: =F22*G22 -> 350000
C23: WC1 | D23: TIEMPO DE PROCESO 1 | E23: MIN | F23: =$D$4*INGENIERIA!F14 -> 175000
C24: WC2 | D24: TIEMPO DE PROCESO 2 | E24: MIN | F24: =$D$4*INGENIERIA!F15 -> 245000
C25: WC3 | D25: TIEMPO DE PROCESO 3 | E25: MIN | F25: =$D$4*INGENIERIA!F16 -> 140000
B27: 9002 | C27: PRODUCTO B
C28: 1001 | D28: MATERIA PRIMA A | E28: KGS | F28: =$D$5*INGENIERIA!F19 -> 8400 | G28: =VLOOKUP(C28,COMPRAS!B:F,4,0) -> 100 | H28: =F28*G28 -> 840000
C29: 1002 | D29: MATERIA PRIMA B | E29: KGS | F29: =$D$5*INGENIERIA!F20 -> 4200 | G29: =VLOOKUP(C29,COMPRAS!B:F,4,0) -> 55 | H29: =F29*G29 -> 231000
C30: 1003 | D30: MATERIA PRIMA C | E30: KGS | F30: =$D$5*INGENIERIA!F21 -> 2688 | G30: =VLOOKUP(C30,COMPRAS!B:F,4,0) -> 20 | H30: =F30*G30 -> 53760
C31: 1004 | D31: MATERIA PRIMA D | E31: KGS | F31: =$D$5*INGENIERIA!F22 -> 16800 | G31: =VLOOKUP(C31,COMPRAS!B:F,4,0) -> 34 | H31: =F31*G31 -> 571200
C32: 1005 | D32: MATERIA PRIMA E | E32: KGS | F32: =$D$5*INGENIERIA!F23 -> 5628 | G32: =VLOOKUP(C32,COMPRAS!B:F,4,0) -> 15 | H32: =F32*G32 -> 84420
C33: 1006 | D33: MATERIA PRIMA F | E33: KGS | F33: =$D$5*INGENIERIA!F24 -> 1680 | G33: =VLOOKUP(C33,COMPRAS!B:F,4,0) -> 67 | H33: =F33*G33 -> 112560
C34: 1007 | D34: MATERIA PRIMA G | E34: KGS | F34: =$D$5*INGENIERIA!F25 -> 840 | G34: =VLOOKUP(C34,COMPRAS!B:F,4,0) -> 22 | H34: =F34*G34 -> 18480
C35: 1008 | D35: MATERIA PRIMA H | E35: KGS | F35: =$D$5*INGENIERIA!F26 -> 6720 | G35: =VLOOKUP(C35,COMPRAS!B:F,4,0) -> 35 | H35: =F35*G35 -> 235200
C36: 1009 | D36: MATERIA PRIMA I | E36: PZA | F36: =$D$5*INGENIERIA!F27 -> 10000 | G36: =VLOOKUP(C36,COMPRAS!B:F,4,0) -> 15 | H36: =F36*G36 -> 150000
C37: 1010 | D37: MATERIA PRIMA J | E37: PZA | F37: =$D$5*INGENIERIA!F28 -> 10000 | G37: =VLOOKUP(C37,COMPRAS!B:F,4,0) -> 10 | H37: =F37*G37 -> 100000
C38: WC1 | D38: TIEMPO DE PROCESO 1 | E38: MIN | F38: =$D$5*INGENIERIA!F29 -> 55000
C39: WC2 | D39: TIEMPO DE PROCESO 2 | E39: MIN | F39: =$D$5*INGENIERIA!F30 -> 77000
C40: WC3 | D40: TIEMPO DE PROCESO 3 | E40: MIN | F40: =$D$5*INGENIERIA!F31 -> 44000
B42: 9003 | C42: PRODUCTO C
C43: 1001 | D43: MATERIA PRIMA A | E43: KGS | F43: =$D$6*INGENIERIA!F34 -> 26250 | G43: =VLOOKUP(C43,COMPRAS!B:F,4,0) -> 100 | H43: =F43*G43 -> 2625000
C44: 1002 | D44: MATERIA PRIMA B | E44: KGS | F44: =$D$6*INGENIERIA!F35 -> 13125 | G44: =VLOOKUP(C44,COMPRAS!B:F,4,0) -> 55 | H44: =F44*G44 -> 721875
...

Sheet VENTA REAL
B2: VALUACION DE LA PRODUCCION
B3: COD | C3: PRODUCTO | D3: ENERO | E3: PRECIO | F3: VENTA BRUTA | G3: DESCUENTOS | H3: VENTA NETA | L3: FCTS KGS | M3: VAR | O3: FCTS VENTAS | P3: VAR | R3: X VOLUMEN | S3: X PRECIO
B4: 9001 | C4: PRODUCTO A | D4: 35000 | E4: =VENTAS!L4 -> 403.44907 | F4: =D4*E4 -> 14120717 | G4: =F4*2% -> 282414.35 | H4: =F4-G4 -> 13838303 | J4: =H4/D4 -> 395.38009 | L4: =VENTAS!D12 -> 25000 | M4: =D4-L4 -> 10000 | O4: =VENTAS!D20 -> 10086227 | P4: =H4-O4 -> 3752076.3 | R4: =M4*E4 -> 4034490.7 | S4: =(J4-E4)*D4 -> -282414.35
